Workbook

Sheet SK
B4: JEOFİZİKTEN VS30 = | D4: 134.7 | E4: m/sn | J4: Mw= | K4: 7 | M4: CE = | N4: 1
C5: Sds= | D5: 0.81 | J5: =CONCATENATE("CM ", K4," = ") -> CM 7 = | K5: =((10^2.24)/(K4^2.56)) -> 1.1927489 | M5: CS = | N5: 1
M6: CB = | N6: 1.1
B8: A BLOK SK-1 | E8: DERİNLİK (m) | H8: YASS (m) | I8: İLK DENEY DERİNLİĞİ
E9: 20 | H9: 2 | I9: 1.5
B10: NUMUNE NO | C10: Derinlik (m) | D10: N1 (0-15) | E10: N2 (15-30) | F10: N3 (30-45) | G10: N30 | H10: Zemin Cinsi | I10: Zemin AÇIKLAMASI | L10: YASS | M10: WN (Doğal su içeriği) | N10: (#10'da kalan ) | O10: IDI % (#200'den geçen ) | P10: LL ( Likit limit ) | Q10: PL ( Plastik limit ) | R10: PI % | S10: γ t/m3 (Doğal Birim Hacim Ağırlık ) | W10: Zemin Cinsi | X10: Zemin AÇIKLAMASI
B11: 1 | C11: 1.5 | D11: 9 | E11: 9 | F11: 13 | G11: =IF(B11="","",E11+F11) -> 22 | H11: ciSa | I11: =IF(H11="","",VLOOKUP(H11,$W$11:$X$25,2,FALSE)) -> Killi Kumlu Zemin | L11: =IF(B11=0," ",$H$9) -> 2 | M11: 19.2 | N11: - | O11: 63.2 | P11: 29.4 | Q11: 19.7 | R11: =IF(B11="","",IF(OR(P11="",Q11="",P11="-",Q11="-"),"",P11-Q11)) -> 9.7 | S11: 1.74
B12: 2 | C12: =IF(B12="","",C11+1.5) -> 3 | D12: 3 | E12: 3 | F12: 2 | G12: =IF(B12="","",E12+F12) -> 5 | H12: CIH | I12: =IF(H12="","",VLOOKUP(H12,$W$11:$X$25,2,FALSE)) -> Yüksek Plastisiteli Kil | L12: =IF(B12=0," ",$H$9) -> 2 | M12: 20.1 | N12: - | O12: 62.2 | P12: 38.1 | Q12: 20.4 | R12: =IF(B12="","",IF(OR(P12="",Q12="",P12="-",Q12="-"),"",P12-Q12)) -> 17.7 | S12: 1.85 | W12: GrW | X12: İyi Granüllü Çakıl
B13: 3 | C13: =IF(B13="","",C12+1.5) -> 4.5 | D13: 3 | E13: 6 | F13: 10 | G13: =IF(B13="","",E13+F13) -> 16 | H13: CIM | I13: =IF(H13="","",VLOOKUP(H13,$W$11:$X$25,2,FALSE)) -> Orta Plastisiteli Kil | L13: =IF(B13=0," ",$H$9) -> 2 | M13: 20.7 | N13: - | O13: 68.5 | P13: 38.2 | Q13: 20.4 | R13: =IF(B13="","",IF(OR(P13="",Q13="",P13="-",Q13="-"),"",P13-Q13)) -> 17.8 | S13: 1.83 | W13: GrM | X13: Siltli Çakıl
B14: 4 | C14: =IF(B14="","",C13+1.5) -> 6 | D14: 5 | E14: 6 | F14: 7 | G14: =IF(B14="","",E14+F14) -> 13 | H14: siSa | I14: =IF(H14="","",VLOOKUP(H14,$W$11:$X$25,2,FALSE)) -> Siltli Kumlu Zemin | L14: =IF(B14=0," ",$H$9) -> 2 | M14: 21.2 | N14: - | O14: 38.1 | R14: =IF(B14="","",IF(OR(P14="",Q14="",P14="-",Q14="-"),"",P14-Q14)) | S14: 1.63 | W14: GrP | X14: Kötü Granüllü Çakıl
B15: 5 | C15: =IF(B15="","",C14+1.5) -> 7.5 | D15: 5 | E15: 5 | F15: 6 | G15: =IF(B15="","",E15+F15) -> 11 | H15: CIM | I15: =IF(H15="","",VLOOKUP(H15,$W$11:$X$25,2,FALSE)) -> Orta Plastisiteli Kil | L15: =IF(B15=0," ",$H$9) -> 2 | M15: 20.8 | N15: - | O15: 65.4 | P15: 37.5 | Q15: 20.5 | R15: =IF(B15="","",IF(OR(P15="",Q15="",P15="-",Q15="-"),"",P15-Q15)) -> 17 | S15: 1.86 | W15: SaW | X15: İyi Granüllü Kum
B16: 6 | C16: =IF(B16="","",C15+1.5) -> 9 | D16: 6 | E16: 7 | F16: 5 | G16: =IF(B16="","",E16+F16) -> 12 | H16: CIL | I16: =IF(H16="","",VLOOKUP(H16,$W$11:$X$25,2,FALSE)) -> Düşük Plastisiteli Kil | L16: =IF(B16=0," ",$H$9) -> 2 | M16: 19.7 | N16: - | O16: 67.8 | P16: 29.9 | Q16: 20.7 | R16: =IF(B16="","",IF(OR(P16="",Q16="",P16="-",Q16="-"),"",P16-Q16)) -> 9.2 | S16: 1.79 | W16: SaM | X16: Siltli Kum
B17: 7 | C17: =IF(B17="","",C16+1.5) -> 10.5 | D17: 4 | E17: 4 | F17: 3 | G17: =IF(B17="","",E17+F17) -> 7 | H17: CIM | I17: =IF(H17="","",VLOOKUP(H17,$W$11:$X$25,2,FALSE)) -> Orta Plastisiteli Kil | L17: =IF(B17=0," ",$H$9) -> 2 | M17: 21.8 | N17: - | O17: 63.9 | P17: 38.7 | Q17: 20.4 | R17: =IF(B17="","",IF(OR(P17="",Q17="",P17="-",Q17="-"),"",P17-Q17)) -> 18.3 | S17: 1.86 | W17: SaP | X17: Kötü Granüllü Kum
B18: 8 | C18: =IF(B18="","",C17+1.5) -> 12 | D18: 5 | E18: 5 | F18: 6 | G18: =IF(B18="","",E18+F18) -> 11 | H18: CIM | I18: =IF(H18="","",VLOOKUP(H18,$W$11:$X$25,2,FALSE)) -> Orta Plastisiteli Kil | L18: =IF(B18=0," ",$H$9) -> 2 | M18: 22.6 | N18: - | O18: 67.7 | P18: 38.1 | Q18: 20 | R18: =IF(B18="","",IF(OR(P18="",Q18="",P18="-",Q18="-"),"",P18-Q18)) -> 18.1 | S18: 1.83 | W18: siSa | X18: Siltli Kumlu Zemin
B19: 9 | C19: =IF(B19="","",C18+1.5) -> 13.5 | D19: 15 | E19: 15 | F19: 20 | G19: =IF(B19="","",E19+F19) -> 35 | H19: CIM | I19: =IF(H19="","",VLOOKUP(H19,$W$11:$X$25,2,FALSE)) -> Orta Plastisiteli Kil | L19: =IF(B19=0," ",$H$9) -> 2 | M19: 23.2 | N19: - | O19: 65.8 | P19: 39.5 | Q19: 19.4 | R19: =IF(B19="","",IF(OR(P19="",Q19="",P19="-",Q19="-"),"",P19-Q19)) -> 20.1 | S19: 1.85 | W19: ciSa | X19: Killi Kumlu Zemin
B20: 10 | C20: =IF(B20="","",C19+1.5) -> 15 | D20: 3 | E20: 4 | F20: 5 | G20: =IF(B20="","",E20+F20) -> 9 | H20: CIM | I20: =IF(H20="","",VLOOKUP(H20,$W$11:$X$25,2,FALSE)) -> Orta Plastisiteli Kil | L20: =IF(B20=0," ",$H$9) -> 2 | M20: 22.5 | N20: - | O20: 62.9 | P20: 38.2 | Q20: 20.4 | R20: =IF(B20="","",IF(OR(P20="",Q20="",P20="-",Q20="-"),"",P20-Q20)) -> 17.8 | S20: 1.84 | W20: CIL | X20: Düşük Plastisiteli Kil
B21: 11 | C21: =IF(B21="","",C20+1.5) -> 16.5 | D21: 4 | E21: 4 | F21: 5 | G21: =IF(B21="","",E21+F21) -> 9 | H21: CIM | I21: =IF(H21="","",VLOOKUP(H21,$W$11:$X$25,2,FALSE)) -> Orta Plastisiteli Kil | L21: =IF(B21=0," ",$H$9) -> 2 | M21: 23.2 | N21: - | O21: 69.4 | P21: 39.6 | Q21: 19.7 | R21: =IF(B21="","",IF(OR(P21="",Q21="",P21="-",Q21="-"),"",P21-Q21)) -> 19.9 | S21: 1.86 | W21: CIM | X21: Orta Plastisiteli Kil
B22: 12 | C22: =IF(B22="","",C21+1.5) -> 18 | D22: 12 | E22: 9 | F22: 13 | G22: =IF(B22="","",E22+F22) -> 22 | H22: CIM | I22: =IF(H22="","",VLOOKUP(H22,$W$11:$X$25,2,FALSE)) -> Orta Plastisiteli Kil | L22: =IF(B22=0," ",$H$9) -> 2 | M22: 22.4 | N22: - | O22: 60.1 | P22: 38.1 | Q22: 20.4 | R22: =IF(B22="","",IF(OR(P22="",Q22="",P22="-",Q22="-"),"",P22-Q22)) -> 17.7 | S22: 1.87 | W22: CIH | X22: Yüksek Plastisiteli Kil
B23: 13 | C23: =IF(B23="","",C22+1.5) -> 19.5 | D23: 11 | E23: 11 | F23: 14 | G23: =IF(B23="","",E23+F23) -> 25 | H23: CIM | I23: =IF(H23="","",VLOOKUP(H23,$W$11:$X$25,2,FALSE)) -> Orta Plastisiteli Kil | L23: =IF(B23=0," ",$H$9) -> 2 | M23: 23.5 | N23: - | O23: 69.2 | P23: 37.5 | Q23: 20.4 | R23: =IF(B23="","",IF(OR(P23="",Q23="",P23="-",Q23="-"),"",P23-Q23)) -> 17.1 | S23: 1.85 | W23: SiL | X23: Düşük Plastisiteli Silt
C24: =IF(B24="","",C23+1.5) | G24: =IF(B24="","",E24+F24) | I24: =IF(H24="","",VLOOKUP(H24,$W$11:$X$25,2,FALSE)) | L24: =IF(B24=0," ",$H$9) | R24: =IF(B24="","",IF(OR(P24="",Q24="",P24="-",Q24="-"),"",P24-Q24)) | W24: SiH | X24: Yüksek Plastisiteli Silt
G25: =IF(B25="","",E25+F25) | I25: =IF(H25="","",VLOOKUP(H25,$W$11:$X$25,2,FALSE)) | L25: =IF(B25=0," ",$H$9) | R25: =IF(B25="","",IF(OR(P25="",Q25="",P25="-",Q25="-"),"",P25-Q25)) | W25: Dolgu | X25: Dolgu
G26: =IF(B26="","",E26+F26) | I26: =IF(H26="","",VLOOKUP(H26,$W$11:$X$25,2,FALSE)) | L26: =IF(B26=0," ",$H$9) | R26: =IF(B26="","",IF(OR(P26="",Q26="",P26="-",Q26="-"),"",P26-Q26))
G27: =IF(B27="","",E27+F27) | I27: =IF(H27="","",VLOOKUP(H27,$W$11:$X$25,2,FALSE)) | L27: =IF(B27=0," ",$H$9) | R27: =IF(B27="","",IF(OR(P27="",Q27="",P27="-",Q27="-"),"",P27-Q27))
G28: =IF(B28="","",E28+F28) | I28: =IF(H28="","",VLOOKUP(H28,$W$11:$X$25,2,FALSE)) | L28: =IF(B28=0," ",$H$9) | R28: =IF(B28="","",IF(OR(P28="",Q28="",P28="-",Q28="-"),"",P28-Q28))
G29: =IF(B29="","",E29+F29) | I29: =IF(H29="","",VLOOKUP(H29,$W$11:$X$25,2,FALSE)) | L29: =IF(B29=0," ",$H$9) | R29: =IF(B29="","",IF(OR(P29="",Q29="",P29="-",Q29="-"),"",P29-Q29))
B33: NOT: SADECE KIRMIZI RENKLİ HÜCRELERE VERİ GİRİŞİ YAPILACAK.

Sheet SIVILASMA ONCESI
B2: JEOFİZİKTEN VS30 = | D2: =SK!D4 -> 134.7 | E2: m/sn | J2: Mw= | K2: =SK!K4 -> 7 | M2: CE = | N2: =SK!N4 -> 1
C3: Sds= | D3: =SK!D5 -> 0.81 | J3: =CONCATENATE("CM ", K2," = ") -> CM 7 = | K3: =((10^2.24)/(K2^2.56)) -> 1.1927489 | M3: CS = | N3: =SK!N5 -> 1
M4: CB = | N4: =SK!N6 -> 1.1
B6: =SK!B8 -> A BLOK SK-1 | E6: DERİNLİK (m) | H6: YASS (m) | I6: İLK DENEY DERİNLİĞİ | AA6: Dakshanamurthy ve Raman (1973)
E7: =SK!E9 -> 20 | H7: =SK!H9 -> 2 | I7: =SK!I9 -> 1.5
B8: NUMUNE NO | C8: Derinlik (m) | D8: N1 (0-15) | E8: N2 (15-30) | F8: N3 (30-45) | G8: N30 | H8: Zemin Cinsi | I8: Zemin AÇIKLAMASI | K8: YASS | L8: WN (Doğal su içeriği) | M8: (#10'da kalan ) | N8: IDI % (#200'den geçen ) | O8: LL ( Likit limit ) | P8: PL ( Plastik limit ) | Q8: PI % | R8: γ t/m3 (Doğal Birim Hacim Ağırlık ) | S8: γ kN/m3 (Doğal Birim Hacim Ağırlık ) | T8: γk Kn/m3 | U8: e (Boşluk Oranı) | V8: γd kN/m3 (Doygun Birim Hacim Ağırlık ) | W8: Derinlik (m) | AA8: ŞİŞME POTANSİYELİ (%)= 0,00216 X (LL)2.44
B9: =SK!B11 -> 1 | C9: =SK!C11 -> 1.5 | D9: =SK!D11 -> 9 | E9: =SK!E11 -> 9 | F9: =SK!F11 -> 13 | G9: =SK!G11 -> 22 | H9: =SK!H11 -> ciSa | I9: =SK!I11 -> Killi Kumlu Zemin | K9: =SK!L11 -> 2 | L9: =SK!M11 -> 19.2 | M9: =SK!N11 -> - | N9: =SK!O11 -> 63.2 | O9: =SK!P11 -> 29.4 | P9: =SK!Q11 -> 19.7 | Q9: =SK!R11 -> 9.7 | R9: =SK!S11 -> 1.74 | S9: =IF(B9="","",R9*9.81) -> 17.0694 | T9: =IF(B9="","",((R9/(1+L9/100))*10)) -> 14.597315 | U9: =IF(B9=0," ",(((2.65*9.81)/T9)-1)) -> 0.78090966 | V9: =IF(B9=0," ",(((2.65+U9)/(1+U9))*9.81)) -> 18.898895 | W9: =IF(B9=0," ",C9) -> 1.5 | AA9: =0.0000216*O9^2.44 -> 0.082645886
B10: =SK!B12 -> 2 | C10: =SK!C12 -> 3 | D10: =SK!D12 -> 3 | E10: =SK!E12 -> 3 | F10: =SK!F12 -> 2 | G10: =SK!G12 -> 5 | H10: =SK!H12 -> CIH | I10: =SK!I12 -> Yüksek Plastisiteli Kil | K10: =SK!L12 -> 2 | L10: =SK!M12 -> 20.1 | M10: =SK!N12 -> - | N10: =SK!O12 -> 62.2 | O10: =SK!P12 -> 38.1 | P10: =SK!Q12 -> 20.4 | Q10: =SK!R12 -> 17.7 | R10: =SK!S12 -> 1.85 | S10: =IF(B10="","",R10*9.81) -> 18.1485 | T10: =IF(B10="","",((R10/(1+L10/100))*10)) -> 15.40383 | U10: =IF(B10=0," ",(((2.65*9.81)/T10)-1)) -> 0.68766468 | V10: =IF(B10=0," ",(((2.65+U10)/(1+U10))*9.81)) -> 19.401064 | W10: =IF(B10=0," ",C10) -> 3 | AA10: =0.0000216*O10^2.44 -> 0.15556457
B11: =SK!B13 -> 3 | C11: =SK!C13 -> 4.5 | D11: =SK!D13 -> 3 | E11: =SK!E13 -> 6 | F11: =SK!F13 -> 10 | G11: =SK!G13 -> 16 | H11: =SK!H13 -> CIM | I11: =SK!I13 -> Orta Plastisiteli Kil | K11: =SK!L13 -> 2 | L11: =SK!M13 -> 20.7 | M11: =SK!N13 -> - | N11: =SK!O13 -> 68.5 | O11: =SK!P13 -> 38.2 | P11: =SK!Q13 -> 20.4 | Q11: =SK!R13 -> 17.8 | R11: =SK!S13 -> 1.83 | S11: =IF(B11="","",R11*9.81) -> 17.9523 | T11: =IF(B11="","",((R11/(1+L11/100))*10)) -> 15.161558 | U11: =IF(B11=0," ",(((2.65*9.81)/T11)-1)) -> 0.71463254 | V11: =IF(B11=0," ",(((2.65+U11)/(1+U11))*9.81)) -> 19.250215 | W11: =IF(B11=0," ",C11) -> 4.5 | AA11: =0.0000216*O11^2.44 -> 0.15656272
B12: =SK!B14 -> 4 | C12: =SK!C14 -> 6 | D12: =SK!D14 -> 5 | E12: =SK!E14 -> 6 | F12: =SK!F14 -> 7 | G12: =SK!G14 -> 13 | H12: =SK!H14 -> siSa | I12: =SK!I14 -> Siltli Kumlu Zemin | K12: =SK!L14 -> 2 | L12: =SK!M14 -> 21.2 | M12: =SK!N14 -> - | N12: =SK!O14 -> 38.1 | O12: =SK!P14 -> 0 | P12: =SK!Q14 -> 0 | Q12: =SK!R14 | R12: =SK!S14 -> 1.63 | S12: =IF(B12="","",R12*9.81) -> 15.9903 | T12: =IF(B12="","",((R12/(1+L12/100))*10)) -> 13.448845 | U12: =IF(B12=0," ",(((2.65*9.81)/T12)-1)) -> 0.93299129 | V12: =IF(B12=0," ",(((2.65+U12)/(1+U12))*9.81)) -> 18.183809 | W12: =IF(B12=0," ",C12) -> 6 | AA12: =0.0000216*O12^2.44 -> 0
B13: =SK!B15 -> 5 | C13: =SK!C15 -> 7.5 | D13: =SK!D15 -> 5 | E13: =SK!E15 -> 5 | F13: =SK!F15 -> 6 | G13: =SK!G15 -> 11 | H13: =SK!H15 -> CIM | I13: =SK!I15 -> Orta Plastisiteli Kil | K13: =SK!L15 -> 2 | L13: =SK!M15 -> 20.8 | M13: =SK!N15 -> - | N13: =SK!O15 -> 65.4 | O13: =SK!P15 -> 37.5 | P13: =SK!Q15 -> 20.5 | Q13: =SK!R15 -> 17 | R13: =SK!S15 -> 1.86 | S13: =IF(B13="","",R13*9.81) -> 18.2466 | T13: =IF(B13="","",((R13/(1+L13/100))*10)) -> 15.397351 | U13: =IF(B13=0," ",(((2.65*9.81)/T13)-1)) -> 0.68837484 | V13: =IF(B13=0," ",(((2.65+U13)/(1+U13))*9.81)) -> 19.39703 | W13: =IF(B13=0," ",C13) -> 7.5 | AA13: =0.0000216*O13^2.44 -> 0.14965459
B14: =SK!B16 -> 6 | C14: =SK!C16 -> 9 | D14: =SK!D16 -> 6 | E14: =SK!E16 -> 7 | F14: =SK!F16 -> 5 | G14: =SK!G16 -> 12 | H14: =SK!H16 -> CIL | I14: =SK!I16 -> Düşük Plastisiteli Kil | K14: =SK!L16 -> 2 | L14: =SK!M16 -> 19.7 | M14: =SK!N16 -> - | N14: =SK!O16 -> 67.8 | O14: =SK!P16 -> 29.9 | P14: =SK!Q16 -> 20.7 | Q14: =SK!R16 -> 9.2 | R14: =SK!S16 -> 1.79 | S14: =IF(B14="","",R14*9.81) -> 17.5599 | T14: =IF(B14="","",((R14/(1+L14/100))*10)) -> 14.954052 | U14: =IF(B14=0," ",(((2.65*9.81)/T14)-1)) -> 0.73842517 | V14: =IF(B14=0," ",(((2.65+U14)/(1+U14))*9.81)) -> 19.121013 | W14: =IF(B14=0," ",C14) -> 9 | AA14: =0.0000216*O14^2.44 -> 0.086117507
B15: =SK!B17 -> 7 | C15: =SK!C17 -> 10.5 | D15: =SK!D17 -> 4 | E15: =SK!E17 -> 4 | F15: =SK!F17 -> 3 | G15: =SK!G17 -> 7 | H15: =SK!H17 -> CIM | I15: =SK!I17 -> Orta Plastisiteli Kil | K15: =SK!L17 -> 2 | L15: =SK!M17 -> 21.8 | M15: =SK!N17 -> - | N15: =SK!O17 -> 63.9 | O15: =SK!P17 -> 38.7 | P15: =SK!Q17 -> 20.4 | Q15: =SK!R17 -> 18.3 | R15: =SK!S17 -> 1.86 | S15: =IF(B15="","",R15*9.81) -> 18.2466 | T15: =IF(B15="","",((R15/(1+L15/100))*10)) -> 15.270936 | U15: =IF(B15=0," ",(((2.65*9.81)/T15)-1)) -> 0.70235145 | V15: =IF(B15=0," ",(((2.65+U15)/(1+U15))*9.81)) -> 19.318319 | W15: =IF(B15=0," ",C15) -> 10.5 | AA15: =0.0000216*O15^2.44 -> 0.1616101
B16: =SK!B18 -> 8 | C16: =SK!C18 -> 12 | D16: =SK!D18 -> 5 | E16: =SK!E18 -> 5 | F16: =SK!F18 -> 6 | G16: =SK!G18 -> 11 | H16: =SK!H18 -> CIM | I16: =SK!I18 -> Orta Plastisiteli Kil | K16: =SK!L18 -> 2 | L16: =SK!M18 -> 22.6 | M16: =SK!N18 -> - | N16: =SK!O18 -> 67.7 | O16: =SK!P18 -> 38.1 | P16: =SK!Q18 -> 20 | Q16: =SK!R18 -> 18.1 | R16: =SK!S18 -> 1.83 | S16: =IF(B16="","",R16*9.81) -> 17.9523 | T16: =IF(B16="","",((R16/(1+L16/100))*10)) -> 14.926591 | U16: =IF(B16=0," ",(((2.65*9.81)/T16)-1)) -> 0.74162344 | V16: =IF(B16=0," ",(((2.65+U16)/(1+U16))*9.81)) -> 19.103915 | W16: =IF(B16=0," ",C16) -> 12 | AA16: =0.0000216*O16^2.44 -> 0.15556457
B17: =SK!B19 -> 9 | C17: =SK!C19 -> 13.5 | D17: =SK!D19 -> 15 | E17: =SK!E19 -> 15 | F17: =SK!F19 -> 20 | G17: =SK!G19 -> 35 | H17: =SK!H19 -> CIM | I17: =SK!I19 -> Orta Plastisiteli Kil | K17: =SK!L19 -> 2 | L17: =SK!M19 -> 23.2 | M17: =SK!N19 -> - | N17: =SK!O19 -> 65.8 | O17: =SK!P19 -> 39.5 | P17: =SK!Q19 -> 19.4 | Q17: =SK!R19 -> 20.1 | R17: =SK!S19 -> 1.85 | S17: =IF(B17="","",R17*9.81) -> 18.1485 | T17: =IF(B17="","",((R17/(1+L17/100))*10)) -> 15.016234 | U17: =IF(B17=0," ",(((2.65*9.81)/T17)-1)) -> 0.73122638 | V17: =IF(B17=0," ",(((2.65+U17)/(1+U17))*9.81)) -> 19.15973 | W17: =IF(B17=0," ",C17) -> 13.5 | AA17: =0.0000216*O17^2.44 -> 0.16988329
B18: =SK!B20 -> 10 | C18: =SK!C20 -> 15 | D18: =SK!D20 -> 3 | E18: =SK!E20 -> 4 | F18: =SK!F20 -> 5 | G18: =SK!G20 -> 9 | H18: =SK!H20 -> CIM | I18: =SK!I20 -> Orta Plastisiteli Kil | K18: =SK!L20 -> 2 | L18: =SK!M20 -> 22.5 | M18: =SK!N20 -> - | N18: =SK!O20 -> 62.9 | O18: =SK!P20 -> 38.2 | P18: =SK!Q20 -> 20.4 | Q18: =SK!R20 -> 17.8 | R18: =SK!S20 -> 1.84 | S18: =IF(B18="","",R18*9.81) -> 18.0504 | T18: =IF(B18="","",((R18/(1+L18/100))*10)) -> 15.020408 | U18: =IF(B18=0," ",(((2.65*9.81)/T18)-1)) -> 0.73074524 | V18: =IF(B18=0," ",(((2.65+U18)/(1+U18))*9.81)) -> 19.16233 | W18: =IF(B18=0," ",C18) -> 15 | AA18: =0.0000216*O18^2.44 -> 0.15656272
B19: =SK!B21 -> 11 | C19: =SK!C21 -> 16.5 | D19: =SK!D21 -> 4 | E19: =SK!E21 -> 4 | F19: =SK!F21 -> 5 | G19: =SK!G21 -> 9 | H19: =SK!H21 -> CIM | I19: =SK!I21 -> Orta Plastisiteli Kil | K19: =SK!L21 -> 2 | L19: =SK!M21 -> 23.2 | M19: =SK!N21 -> - | N19: =SK!O21 -> 69.4 | O19: =SK!P21 -> 39.6 | P19: =SK!Q21 -> 19.7 | Q19: =SK!R21 -> 19.9 | R19: =SK!S21 -> 1.86 | S19: =IF(B19="","",R19*9.81) -> 18.2466 | T19: =IF(B19="","",((R19/(1+L19/100))*10)) -> 15.097403 | U19: =IF(B19=0," ",(((2.65*9.81)/T19)-1)) -> 0.72191871 | V19: =IF(B19=0," ",(((2.65+U19)/(1+U19))*9.81)) -> 19.21027 | W19: =IF(B19=0," ",C19) -> 16.5 | AA19: =0.0000216*O19^2.44 -> 0.17093461
B20: =SK!B22 -> 12 | C20: =SK!C22 -> 18 | D20: =SK!D22 -> 12 | E20: =SK!E22 -> 9 | F20: =SK!F22 -> 13 | G20: =SK!G22 -> 22 | H20: =SK!H22 -> CIM | I20: =SK!I22 -> Orta Plastisiteli Kil | K20: =SK!L22 -> 2 | L20: =SK!M22 -> 22.4 | M20: =SK!N22 -> - | N20: =SK!O22 -> 60.1 | O20: =SK!P22 -> 38.1 | P20: =SK!Q22 -> 20.4 | Q20: =SK!R22 -> 17.7 | R20: =SK!S22 -> 1.87 | S20: =IF(B20="","",R20*9.81) -> 18.3447 | T20: =IF(B20="","",((R20/(1+L20/100))*10)) -> 15.277778 | U20: =IF(B20=0," ",(((2.65*9.81)/T20)-1)) -> 0.70158909 | V20: =IF(B20=0," ",(((2.65+U20)/(1+U20))*9.81)) -> 19.322579 | W20: =IF(B20=0," ",C20) -> 18 | AA20: =0.0000216*O20^2.44 -> 0.15556457
B21: =SK!B23 -> 13 | C21: =SK!C23 -> 19.5 | D21: =SK!D23 -> 11 | E21: =SK!E23 -> 11 | F21: =SK!F23 -> 14 | G21: =SK!G23 -> 25 | H21: =SK!H23 -> CIM | I21: =SK!I23 -> Orta Plastisiteli Kil | K21: =SK!L23 -> 2 | L21: =SK!M23 -> 23.5 | M21: =SK!N23 -> - | N21: =SK!O23 -> 69.2 | O21: =SK!P23 -> 37.5 | P21: =SK!Q23 -> 20.4 | Q21: =SK!R23 -> 17.1 | R21: =SK!S23 -> 1.85 | S21: =IF(B21="","",R21*9.81) -> 18.1485 | T21: =IF(B21="","",((R21/(1+L21/100))*10)) -> 14.979757 | U21: =IF(B21=0," ",(((2.65*9.81)/T21)-1)) -> 0.73544203 | V21: =IF(B21=0," ",(((2.65+U21)/(1+U21))*9.81)) -> 19.137019 | W21: =IF(B21=0," ",C21) -> 19.5 | AA21: =0.0000216*O21^2.44 -> 0.14965459
B22: =SK!B24 -> 0 | C22: =SK!C24 | D22: =SK!D24 -> 0 | E22: =SK!E24 -> 0 | F22: =SK!F24 -> 0 | G22: =SK!G24 | H22: =SK!H24 -> 0 | I22: =SK!I24 | K22: =SK!L24 | L22: =SK!M24 -> 0 | M22: =SK!N24 -> 0 | N22: =SK!O24 -> 0 | O22: =SK!P24 -> 0 | P22: =SK!Q24 -> 0 | Q22: =SK!R24 | R22: =SK!S24 -> 0 | S22: =IF(B22="","",R22*9.81) -> 0 | T22: =IF(B22="","",((R22/(1+L22/100))*10)) -> 0 | U22: =IF(B22=0," ",(((2.65*9.81)/T22)-1)) | V22: =IF(B22=0," ",(((2.65+U22)/(1+U22))*9.81)) | W22: =IF(B22=0," ",C22)
B23: =SK!B25 -> 0 | C23: =SK!C25 -> 0 | D23: =SK!D25 -> 0 | E23: =SK!E25 -> 0 | F23: =SK!F25 -> 0 | G23: =SK!G25 | H23: =SK!H25 -> 0 | I23: =SK!I25 | K23: =SK!L25 | L23: =SK!M25 -> 0 | M23: =SK!N25 -> 0 | N23: =SK!O25 -> 0 | O23: =SK!P25 -> 0 | P23: =SK!Q25 -> 0 | Q23: =SK!R25 | R23: =SK!S25 -> 0 | S23: =IF(B23="","",R23*9.81) -> 0 | T23: =IF(B23="","",((R23/(1+L23/100))*10)) -> 0 | U23: =IF(B23=0," ",(((2.65*9.81)/T23)-1)) | V23: =IF(B23=0," ",(((2.65+U23)/(1+U23))*9.81)) | W23: =IF(B23=0," ",C23)
B24: =SK!B26 -> 0 | C24: =SK!C26 -> 0 | D24: =SK!D26 -> 0 | E24: =SK!E26 -> 0 | F24: =SK!F26 -> 0 | G24: =SK!G26 | H24: =SK!H26 -> 0 | I24: =SK!I26 | K24: =SK!L26 | L24: =SK!M26 -> 0 | M24: =SK!N26 -> 0 | N24: =SK!O26 -> 0 | O24: =SK!P26 -> 0 | P24: =SK!Q26 -> 0 | Q24: =SK!R26 | R24: =SK!S26 -> 0 | S24: =IF(B24="","",R24*9.81) -> 0 | T24: =IF(B24="","",((R24/(1+L24/100))*10)) -> 0 | U24: =IF(B24=0," ",(((2.65*9.81)/T24)-1)) | V24: =IF(B24=0," ",(((2.65+U24)/(1+U24))*9.81)) | W24: =IF(B24=0," ",C24)
B25: =SK!B27 -> 0 | C25: =SK!C27 -> 0 | D25: =SK!D27 -> 0 | E25: =SK!E27 -> 0 | F25: =SK!F27 -> 0 | G25: =SK!G27 | H25: =SK!H27 -> 0 | I25: =SK!I27 | K25: =SK!L27 | L25: =SK!M27 -> 0 | M25: =SK!N27 -> 0 | N25: =SK!O27 -> 0 | O25: =SK!P27 -> 0 | P25: =SK!Q27 -> 0 | Q25: =SK!R27 | R25: =SK!S27 -> 0 | S25: =IF(B25="","",R25*9.81) -> 0 | T25: =IF(B25="","",((R25/(1+L25/100))*10)) -> 0 | U25: =IF(B25=0," ",(((2.65*9.81)/T25)-1)) | V25: =IF(B25=0," ",(((2.65+U25)/(1+U25))*9.81)) | W25: =IF(B25=0," ",C25)
B26: =SK!B28 -> 0 | C26: =SK!C28 -> 0 | D26: =SK!D28 -> 0 | E26: =SK!E28 -> 0 | F26: =SK!F28 -> 0 | G26: =SK!G28 | H26: =SK!H28 -> 0 | I26: =SK!I28 | K26: =SK!L28 | L26: =SK!M28 -> 0 | M26: =SK!N28 -> 0 | N26: =SK!O28 -> 0 | O26: =SK!P28 -> 0 | P26: =SK!Q28 -> 0 | Q26: =SK!R28 | R26: =SK!S28 -> 0 | S26: =IF(B26="","",R26*9.81) -> 0 | T26: =IF(B26="","",((R26/(1+L26/100))*10)) -> 0 | U26: =IF(B26=0," ",(((2.65*9.81)/T26)-1)) | V26: =IF(B26=0," ",(((2.65+U26)/(1+U26))*9.81)) | W26: =IF(B26=0," ",C26)
B27: =SK!B29 -> 0 | C27: =SK!C29 -> 0 | D27: =SK!D29 -> 0 | E27: =SK!E29 -> 0 | F27: =SK!F29 -> 0 | G27: =SK!G29 | H27: =SK!H29 -> 0 | I27: =SK!I29 | K27: =SK!L29 | L27: =SK!M29 -> 0 | M27: =SK!N29 -> 0 | N27: =SK!O29 -> 0 | O27: =SK!P29 -> 0 | P27: =SK!Q29 -> 0 | Q27: =SK!R29 | R27: =SK!S29 -> 0 | S27: =IF(B27="","",R27*9.81) -> 0 | T27: =IF(B27="","",((R27/(1+L27/100))*10)) -> 0 | U27: =IF(B27=0," ",(((2.65*9.81)/T27)-1)) | V27: =IF(B27=0," ",(((2.65+U27)/(1+U27))*9.81)) | W27: =IF(B27=0," ",C27)
P29: ORT= | Q29: =AVERAGE(Q9:Q27) -> 16.7 | R29: =AVERAGE(R9:R27) -> 1.2452632 | S29: =AVERAGE(S9:S27) -> 12.216032 | T29: =AVERAGE(T9:T27) -> 10.239582 | U29: =AVERAGE(U9:U27) -> 0.73906881 | V29: =AVERAGE(V9:V27) -> 19.128168

Sheet SIVILASMA
H3: SIVILAŞMA ANALİZİ
B6: JEOFİZİKTEN VS30 = | D6: =SK!D4 -> 134.7 | E6: m/sn | J6: Mw= | K6: =SK!K4 -> 7 | M6: CE = | N6: =SK!N4 -> 1
C7: Sds= | D7: =SK!D5 -> 0.81 | J7: =CONCATENATE("CM ", K6," = ") -> CM 7 = | K7: =((10^2.24)/(K6^2.56)) -> 1.1927489 | M7: CS = | N7: =SK!N5 -> 1
M8: CB = | N8: =SK!N6 -> 1.1
G9: =IF(B9="","",E9+F9) | I9: =IF(H9="","",VLOOKUP(H9,#REF!,2,FALSE))
B10: =SK!B8 -> A BLOK SK-1 | E10: DERİNLİK (m) | H10: YASS (m) | I10: İLK DENEY DERİNLİĞİ
E11: =SK!E9 -> 20 | H11: =SK!H9 -> 2 | I11: =SK!I9 -> 1.5 | AF11: SIVILAŞMA GENEL KONTROL AÇIKLAMA
B12: NUMUNE NO | C12: Derinlik (m) | D12: Zemin Cinsi | E12: N30 | F12: CE | G12: CS | H12: CB | I12: CR (tij boyu düzeltme katsayısı) | J12: N60 | K12: σvo Düşey Gerilme (Kn/m2) | L12: σ'vo Efektif Gerilme (Kn/m2) | M12: CN | N12: N1(60) | O12: α | P12: β | Q12: N1(60)f | R12: rd | S12: N60(30) | T12: SDs | U12: CRR M7,5 | V12: CM7 | W12: τR | X12: τ Deprem | Y12: Ic (kıvam indisi) | Z12: GS | AA12: WN/LL | AB12: SONUÇ | AC12: AÇIKLAMA | AD12: Derinlik (m) | AF12: Zemin Cinsi | AG12: PI % | AH12: LL ( Likit limit ) | AI12: WN/LL
B13: ='SIVILASMA ONCESI'!B9 -> 1 | C13: ='SIVILASMA ONCESI'!C9 -> 1.5 | D13: ='SIVILASMA ONCESI'!H9 -> ciSa | E13: =SK!G11 -> 22 | F13: =IF(B13=0," ",$N$6) -> 1 | G13: =IF(B13=0," ",$N$7) -> 1 | H13: =IF(B13=0," ",$N$8) -> 1.1 | I13: =IF(B13=0," ",IF(AND(C13<4),0.75,IF(AND(4<=C13,C13<6),0.85,IF(AND(6<=C13,C13<10),0.95,IF(AND(10<=C13),1))))) -> 0.75 | J13: =IF(B13=0," ",E13*F13*G13*H13*I13) -> 18.15 | K13: =IF(B13=0," ",IF(C13<$H$11,C13*'SIVILASMA ONCESI'!T9,2)) -> 21.895973 | L13: =IF(B13=0," ",IF(C13<$H$11,K13,K13-(C13-$H$11)*9.81)) -> 21.895973 | M13: =IF(B13=0,"",IF(OR(D13="CIL",D13="CIH",D13="CIM"),1,IF(C13<$H$11,1,9.78*(1/L13)^0.5))) -> 1 | N13: =IF(B13=0," ",M13*J13) -> 18.15 | O13: =IF(B13=0," ",IF('SIVILASMA ONCESI'!N9<5,0,IF('SIVILASMA ONCESI'!N9>35,5,2.71828^(1.76-190/'SIVILASMA ONCESI'!N9^2)))) -> 5 | P13: =IF(B13=0," ",IF('SIVILASMA ONCESI'!N9<5,1,IF('SIVILASMA ONCESI'!N9>35,1.2,0.99+'SIVILASMA ONCESI'!N9^1.5/1000))) -> 1.2 | Q13: =IF(B13=0," ",(O13+P13*N13)) -> 26.78 | R13: =IF(B13=0," ",IF(C13<=9.15,1-0.00765*C13,IF(C13<=23,1.174-0.0267*C13,IF(C13<=30,0.744-0.008*C13,0.5)))) -> 0.988525 | S13: =IF(B13=0," ",IF(C14="",(1.5/J13),(C14-C13)/J13)) -> 0.082644628 | T13: =IF(B13=0," ",SK!$D$5) -> 0.81 | U13: =IF(B13=0," ",(1/(34-Q13)+(Q13/135)+(50/(10*Q13+45)^2)-(1/200))) -> 0.33238554 | V13: =IF(B13=0," ",$K$7) -> 1.1927489 | W13: =IF(B13=0," ",U13*V13*L13) -> 8.680713 | X13: =IF(B13=0," ",0.65*K13*0.4*T13*R13) -> 4.5583774 | Y13: =IF(B13=0," ",('SIVILASMA ONCESI'!O9-'SIVILASMA ONCESI'!L9)/('SIVILASMA ONCESI'!O9-'SIVILASMA ONCESI'!P9)) -> 1.0515464 | Z13: =IF(B13=0," ",IF(Q13>34,2,W13/X13)) -> 1.9043428 | AA13: =IF(B13="","",IF(OR(ISBLANK(SK!P11),SK!P11="-")," ",SK!M11/SK!P11)) -> 0.65306122 | AB13: Y.A.S.S. ÜSTÜ | AC13: Y.A.S.S. ÜSTÜ | AD13: =IF(B13="","",C13) -> 1.5 | AF13: =D13 -> ciSa | AG13: =SK!R11 -> 9.7 | AH13: ='SIVILASMA ONCESI'!O9 -> 29.4 | AI13: =AA13 -> 0.65306122 | AK13: Y.A.S.S. ÜSTÜ
B14: ='SIVILASMA ONCESI'!B10 -> 2 | C14: ='SIVILASMA ONCESI'!C10 -> 3 | D14: ='SIVILASMA ONCESI'!H10 -> CIH | E14: =SK!G12 -> 5 | F14: =IF(B14=0," ",$N$6) -> 1 | G14: =IF(B14=0," ",$N$7) -> 1 | H14: =IF(B14=0," ",$N$8) -> 1.1 | I14: =IF(B14=0," ",IF(AND(C14<4),0.75,IF(AND(4<=C14,C14<6),0.85,IF(AND(6<=C14,C14<10),0.95,IF(AND(10<=C14),1))))) -> 0.75 | J14: =IF(B14=0," ",E14*F14*G14*H14*I14) -> 4.125 | K14: =IF(B14=0," ",C14*'SIVILASMA ONCESI'!T10) -> 46.21149 | L14: =IF(B14=0," ",IF(C14<$H$11,K14,K14-(C14-$H$11)*9.81)) -> 36.40149 | M14: =IF(B14=0,"",IF(OR(D14="CIL",D14="CIH",D14="CIM"),1,IF(C14<$H$11,1,9.78*(1/L14)^0.5))) -> 1 | N14: =IF(B14=0," ",M14*J14) -> 4.125 | O14: =IF(B14=0," ",IF('SIVILASMA ONCESI'!N10<5,0,IF('SIVILASMA ONCESI'!N10>35,5,2.71828^(1.76-190/'SIVILASMA ONCESI'!N10^2)))) -> 5 | P14: =IF(B14=0," ",IF('SIVILASMA ONCESI'!N10<5,1,IF('SIVILASMA ONCESI'!N10>35,1.2,0.99+'SIVILASMA ONCESI'!N10^1.5/1000))) -> 1.2 | Q14: =IF(B14=0," ",(O14+P14*N14)) -> 9.95 | R14: =IF(B14=0," ",IF(C14<=9.15,1-0.00765*C14,IF(C14<=23,1.174-0.0267*C14,IF(C14<=30,0.744-0.008*C14,0.5)))) -> 0.97705 | S14: =IF(B14=0," ",IF(C15="",(1.5/J14),(C15-C14)/J14)) -> 0.36363636 | T14: =IF(B14=0," ",SK!$D$5) -> 0.81 | U14: =IF(B14=0," ",(1/(34-Q14)+(Q14/135)+(50/(10*Q14+45)^2)-(1/200))) -> 0.11267835 | V14: =IF(B14=0," ",$K$7) -> 1.1927489 | W14: =IF(B14=0," ",U14*V14*L14) -> 4.8922503 | X14: =IF(B14=0," ",0.65*K14*0.4*T14*R14) -> 9.5087873 | Y14: =IF(B14=0," ",('SIVILASMA ONCESI'!O10-'SIVILASMA ONCESI'!L10)/('SIVILASMA ONCESI'!O10-'SIVILASMA ONCESI'!P10)) -> 1.0169492 | Z14: =IF(B14=0," ",IF(Q14>34,2,W14/X14)) -> 0.51449782 | AA14: =IF(B14="","",IF(OR(ISBLANK(SK!P12),SK!P12="-")," ",SK!M12/SK!P12)) -> 0.52755906 | AB14: SIVILAŞMA YOK | AC14: GS > 1,1 | AD14: =IF(B14="","",C14) -> 3 | AF14: =D14 -> CIH | AG14: =SK!R12 -> 17.7 | AH14: ='SIVILASMA ONCESI'!O10 -> 38.1 | AI14: =AA14 -> 0.52755906 | AK14: GS > 1,1
B15: ='SIVILASMA ONCESI'!B11 -> 3 | C15: ='SIVILASMA ONCESI'!C11 -> 4.5 | D15: ='SIVILASMA ONCESI'!H11 -> CIM | E15: =SK!G13 -> 16 | F15: =IF(B15=0," ",$N$6) -> 1 | G15: =IF(B15=0," ",$N$7) -> 1 | H15: =IF(B15=0," ",$N$8) -> 1.1 | I15: =IF(B15=0," ",IF(AND(C15<4),0.75,IF(AND(4<=C15,C15<6),0.85,IF(AND(6<=C15,C15<10),0.95,IF(AND(10<=C15),1))))) -> 0.85 | J15: =IF(B15=0," ",E15*F15*G15*H15*I15) -> 14.96 | K15: =IF(B15=0," ",C15*'SIVILASMA ONCESI'!T11) -> 68.227009 | L15: =IF(B15=0," ",IF(C15<$H$11,K15,K15-(C15-$H$11)*9.81)) -> 43.702009 | M15: =IF(B15=0,"",IF(OR(D15="CIL",D15="CIH",D15="CIM"),1,IF(C15<$H$11,1,9.78*(1/L15)^0.5))) -> 1 | N15: =IF(B15=0," ",M15*J15) -> 14.96 | O15: =IF(B15=0," ",IF('SIVILASMA ONCESI'!N11<5,0,IF('SIVILASMA ONCESI'!N11>35,5,2.71828^(1.76-190/'SIVILASMA ONCESI'!N11^2)))) -> 5 | P15: =IF(B15=0," ",IF('SIVILASMA ONCESI'!N11<5,1,IF('SIVILASMA ONCESI'!N11>35,1.2,0.99+'SIVILASMA ONCESI'!N11^1.5/1000))) -> 1.2 | Q15: =IF(B15=0," ",(O15+P15*N15)) -> 22.952 | R15: =IF(B15=0," ",IF(C15<=9.15,1-0.00765*C15,IF(C15<=23,1.174-0.0267*C15,IF(C15<=30,0.744-0.008*C15,0.5)))) -> 0.965575 | S15: =IF(B15=0," ",IF(C16="",(1.5/J15),(C16-C15)/J15)) -> 0.10026738 | T15: =IF(B15=0," ",SK!$D$5) -> 0.81 | U15: =IF(B15=0," ",(1/(34-Q15)+(Q15/135)+(50/(10*Q15+45)^2)-(1/200))) -> 0.25619241 | V15: =IF(B15=0," ",$K$7) -> 1.1927489 | W15: =IF(B15=0," ",U15*V15*L15) -> 13.354163 | X15: =IF(B15=0," ",0.65*K15*0.4*T15*R15) -> 13.873969 | Y15: =IF(B15=0," ",('SIVILASMA ONCESI'!O11-'SIVILASMA ONCESI'!L11)/('SIVILASMA ONCESI'!O11-'SIVILASMA ONCESI'!P11)) -> 0.98314607 | Z15: =IF(B15=0," ",IF(Q15>34,2,W15/X15)) -> 0.96253374 | AA15: =IF(B15="","",IF(OR(ISBLANK(SK!P13),SK!P13="-")," ",SK!M13/SK!P13)) -> 0.54188482 | AB15: SIVILAŞMA YOK | AC15: (PI%> 12) | AD15: =IF(B15="","",C15) -> 4.5 | AF15: =D15 -> CIM | AG15: =SK!R13 -> 17.8 | AH15: ='SIVILASMA ONCESI'!O11 -> 38.2 | AI15: =AA15 -> 0.54188482 | AK15: (PI%> 12)
B16: ='SIVILASMA ONCESI'!B12 -> 4 | C16: ='SIVILASMA ONCESI'!C12 -> 6 | D16: ='SIVILASMA ONCESI'!H12 -> siSa | E16: =SK!G14 -> 13 | F16: =IF(B16=0," ",$N$6) -> 1 | G16: =IF(B16=0," ",$N$7) -> 1 | H16: =IF(B16=0," ",$N$8) -> 1.1 | I16: =IF(B16=0," ",IF(AND(C16<4),0.75,IF(AND(4<=C16,C16<6),0.85,IF(AND(6<=C16,C16<10),0.95,IF(AND(10<=C16),1))))) -> 0.95 | J16: =IF(B16=0," ",E16*F16*G16*H16*I16) -> 13.585 | K16: =IF(B16=0," ",C16*'SIVILASMA ONCESI'!T12) -> 80.693069 | L16: =IF(B16=0," ",IF(C16<$H$11,K16,K16-(C16-$H$11)*9.81)) -> 41.453069 | M16: =IF(B16=0,"",IF(OR(D16="CIL",D16="CIH",D16="CIM"),1,IF(C16<$H$11,1,9.78*(1/L16)^0.5))) -> 1.5190096 | N16: =IF(B16=0," ",M16*J16) -> 20.635745 | O16: =IF(B16=0," ",IF('SIVILASMA ONCESI'!N12<5,0,IF('SIVILASMA ONCESI'!N12>35,5,2.71828^(1.76-190/'SIVILASMA ONCESI'!N12^2)))) -> 5 | P16: =IF(B16=0," ",IF('SIVILASMA ONCESI'!N12<5,1,IF('SIVILASMA ONCESI'!N12>35,1.2,0.99+'SIVILASMA ONCESI'!N12^1.5/1000))) -> 1.2 | Q16: =IF(B16=0," ",(O16+P16*N16)) -> 29.762894 | R16: =IF(B16=0," ",IF(C16<=9.15,1-0.00765*C16,IF(C16<=23,1.174-0.0267*C16,IF(C16<=30,0.744-0.008*C16,0.5)))) -> 0.9541 | S16: =IF(B16=0," ",IF(C17="",(1.5/J16),(C17-C16)/J16)) -> 0.1104159 | T16: =IF(B16=0," ",SK!$D$5) -> 0.81 | U16: =IF(B16=0," ",(1/(34-Q16)+(Q16/135)+(50/(10*Q16+45)^2)-(1/200))) -> 0.45190194 | V16: =IF(B16=0," ",$K$7) -> 1.1927489 | W16: =IF(B16=0," ",U16*V16*L16) -> 22.343433 | X16: =IF(B16=0," ",0.65*K16*0.4*T16*R16) -> 16.213938 | Y16: =IF(B16=0," ",('SIVILASMA ONCESI'!O12-'SIVILASMA ONCESI'!L12)/('SIVILASMA ONCESI'!O12-'SIVILASMA ONCESI'!P12)) -> #DIV/0! | Z16: =IF(B16=0," ",IF(Q16>34,2,W16/X16)) -> 1.3780387 | AA16: =IF(B16="","",IF(OR(ISBLANK(SK!P14),SK!P14="-")," ",SK!M14/SK!P14)) | AB16: SIVILAŞMA YOK | AC16: GS > 1,1 | AD16: =IF(B16="","",C16) -> 6 | AF16: =D16 -> siSa | AG16: =SK!R14 | AH16: ='SIVILASMA ONCESI'!O12 -> 0 | AI16: =AA16 | AK16: (PI%< 12 - WN/LL>0,5)
B17: ='SIVILASMA ONCESI'!B13 -> 5 | C17: ='SIVILASMA ONCESI'!C13 -> 7.5 | D17: ='SIVILASMA ONCESI'!H13 -> CIM | E17: =SK!G15 -> 11 | F17: =IF(B17=0," ",$N$6) -> 1 | G17: =IF(B17=0," ",$N$7) -> 1 | H17: =IF(B17=0," ",$N$8) -> 1.1 | I17: =IF(B17=0," ",IF(AND(C17<4),0.75,IF(AND(4<=C17,C17<6),0.85,IF(AND(6<=C17,C17<10),0.95,IF(AND(10<=C17),1))))) -> 0.95 | J17: =IF(B17=0," ",E17*F17*G17*H17*I17) -> 11.495 | K17: =IF(B17=0," ",C17*'SIVILASMA ONCESI'!T13) -> 115.48013 | L17: =IF(B17=0," ",IF(C17<$H$11,K17,K17-(C17-$H$11)*9.81)) -> 61.525132 | M17: =IF(B17=0,"",IF(OR(D17="CIL",D17="CIH",D17="CIM"),1,IF(C17<$H$11,1,9.78*(1/L17)^0.5))) -> 1 | N17: =IF(B17=0," ",M17*J17) -> 11.495 | O17: =IF(B17=0," ",IF('SIVILASMA ONCESI'!N13<5,0,IF('SIVILASMA ONCESI'!N13>35,5,2.71828^(1.76-190/'SIVILASMA ONCESI'!N13^2)))) -> 5 | P17: =IF(B17=0," ",IF('SIVILASMA ONCESI'!N13<5,1,IF('SIVILASMA ONCESI'!N13>35,1.2,0.99+'SIVILASMA ONCESI'!N13^1.5/1000))) -> 1.2 | Q17: =IF(B17=0," ",(O17+P17*N17)) -> 18.794 | R17: =IF(B17=0," ",IF(C17<=9.15,1-0.00765*C17,IF(C17<=23,1.174-0.0267*C17,IF(C17<=30,0.744-0.008*C17,0.5)))) -> 0.942625 | S17: =IF(B17=0," ",IF(C18="",(1.5/J17),(C18-C17)/J17)) -> 0.13049152 | T17: =IF(B17=0," ",SK!$D$5) -> 0.81 | U17: =IF(B17=0," ",(1/(34-Q17)+(Q17/135)+(50/(10*Q17+45)^2)-(1/200))) -> 0.2008998 | V17: =IF(B17=0," ",$K$7) -> 1.1927489 | W17: =IF(B17=0," ",U17*V17*L17) -> 14.742838 | X17: =IF(B17=0," ",0.65*K17*0.4*T17*R17) -> 22.924749 | Y17: =IF(B17=0," ",('SIVILASMA ONCESI'!O13-'SIVILASMA ONCESI'!L13)/('SIVILASMA ONCESI'!O13-'SIVILASMA ONCESI'!P13)) -> 0.98235294 | Z17: =IF(B17=0," ",IF(Q17>34,2,W17/X17)) -> 0.643097 | AA17: =IF(B17="","",IF(OR(ISBLANK(SK!P15),SK!P15="-")," ",SK!M15/SK!P15)) -> 0.55466667 | AB17: SIVILAŞMA YOK | AC17: (PI%> 12) | AD17: =IF(B17="","",C17) -> 7.5 | AF17: =D17 -> CIM | AG17: =SK!R15 -> 17 | AH17: ='SIVILASMA ONCESI'!O13 -> 37.5 | AI17: =AA17 -> 0.55466667
B18: ='SIVILASMA ONCESI'!B14 -> 6 | C18: ='SIVILASMA ONCESI'!C14 -> 9 | D18: ='SIVILASMA ONCESI'!H14 -> CIL | E18: =SK!G16 -> 12 | F18: =IF(B18=0," ",$N$6) -> 1 | G18: =IF(B18=0," ",$N$7) -> 1 | H18: =IF(B18=0," ",$N$8) -> 1.1 | I18: =IF(B18=0," ",IF(AND(C18<4),0.75,IF(AND(4<=C18,C18<6),0.85,IF(AND(6<=C18,C18<10),0.95,IF(AND(10<=C18),1))))) -> 0.95 | J18: =IF(B18=0," ",E18*F18*G18*H18*I18) -> 12.54 | K18: =IF(B18=0," ",C18*'SIVILASMA ONCESI'!T14) -> 134.58647 | L18: =IF(B18=0," ",IF(C18<$H$11,K18,K18-(C18-$H$11)*9.81)) -> 65.916466 | M18: =IF(B18=0,"",IF(OR(D18="CIL",D18="CIH",D18="CIM"),1,IF(C18<$H$11,1,9.78*(1/L18)^0.5))) -> 1 | N18: =IF(B18=0," ",M18*J18) -> 12.54 | O18: =IF(B18=0," ",IF('SIVILASMA ONCESI'!N14<5,0,IF('SIVILASMA ONCESI'!N14>35,5,2.71828^(1.76-190/'SIVILASMA ONCESI'!N14^2)))) -> 5 | P18: =IF(B18=0," ",IF('SIVILASMA ONCESI'!N14<5,1,IF('SIVILASMA ONCESI'!N14>35,1.2,0.99+'SIVILASMA ONCESI'!N14^1.5/1000))) -> 1.2 | Q18: =IF(B18=0," ",(O18+P18*N18)) -> 20.048 | R18: =IF(B18=0," ",IF(C18<=9.15,1-0.00765*C18,IF(C18<=23,1.174-0.0267*C18,IF(C18<=30,0.744-0.008*C18,0.5)))) -> 0.93115 | S18: =IF(B18=0," ",IF(C19="",(1.5/J18),(C19-C18)/J18)) -> 0.11961722 | T18: =IF(B18=0," ",SK!$D$5) -> 0.81 | U18: =IF(B18=0," ",(1/(34-Q18)+(Q18/135)+(50/(10*Q18+45)^2)-(1/200))) -> 0.21600775 | V18: =IF(B18=0," ",$K$7) -> 1.1927489 | W18: =IF(B18=0," ",U18*V18*L18) -> 16.982916 | X18: =IF(B18=0," ",0.65*K18*0.4*T18*R18) -> 26.392432 | Y18: =IF(B18=0," ",('SIVILASMA ONCESI'!O14-'SIVILASMA ONCESI'!L14)/('SIVILASMA ONCESI'!O14-'SIVILASMA ONCESI'!P14)) -> 1.1086957 | Z18: =IF(B18=0," ",IF(Q18>34,2,W18/X18)) -> 0.64347675 | AA18: =IF(B18="","",IF(OR(ISBLANK(SK!P16),SK!P16="-")," ",SK!M16/SK!P16)) -> 0.65886288 | AB18: SIVILAŞMA YOK | AC18: (PI%< 12 - WN/LL>0,5) | AD18: =IF(B18="","",C18) -> 9 | AF18: =D18 -> CIL | AG18: =SK!R16 -> 9.2 | AH18: ='SIVILASMA ONCESI'!O14 -> 29.9 | AI18: =AA18 -> 0.65886288
B19: ='SIVILASMA ONCESI'!B15 -> 7 | C19: ='SIVILASMA ONCESI'!C15 -> 10.5 | D19: ='SIVILASMA ONCESI'!H15 -> CIM | E19: =SK!G17 -> 7 | F19: =IF(B19=0," ",$N$6) -> 1 | G19: =IF(B19=0," ",$N$7) -> 1 | H19: =IF(B19=0," ",$N$8) -> 1.1 | I19: =IF(B19=0," ",IF(AND(C19<4),0.75,IF(AND(4<=C19,C19<6),0.85,IF(AND(6<=C19,C19<10),0.95,IF(AND(10<=C19),1))))) -> 1 | J19: =IF(B19=0," ",E19*F19*G19*H19*I19) -> 7.7 | K19: =IF(B19=0," ",C19*'SIVILASMA ONCESI'!T15) -> 160.34483 | L19: =IF(B19=0," ",IF(C19<$H$11,K19,K19-(C19-$H$11)*9.81)) -> 76.959828 | M19: =IF(B19=0,"",IF(OR(D19="CIL",D19="CIH",D19="CIM"),1,IF(C19<$H$11,1,9.78*(1/L19)^0.5))) -> 1 | N19: =IF(B19=0," ",M19*J19) -> 7.7 | O19: =IF(B19=0," ",IF('SIVILASMA ONCESI'!N15<5,0,IF('SIVILASMA ONCESI'!N15>35,5,2.71828^(1.76-190/'SIVILASMA ONCESI'!N15^2)))) -> 5 | P19: =IF(B19=0," ",IF('SIVILASMA ONCESI'!N15<5,1,IF('SIVILASMA ONCESI'!N15>35,1.2,0.99+'SIVILASMA ONCESI'!N15^1.5/1000))) -> 1.2 | Q19: =IF(B19=0," ",(O19+P19*N19)) -> 14.24 | R19: =IF(B19=0," ",IF(C19<=9.15,1-0.00765*C19,IF(C19<=23,1.174-0.0267*C19,IF(C19<=30,0.744-0.008*C19,0.5)))) -> 0.89365 | S19: =IF(B19=0," ",IF(C20="",(1.5/J19),(C20-C19)/J19)) -> 0.19480519 | T19: =IF(B19=0," ",SK!$D$5) -> 0.81 | U19: =IF(B19=0," ",(1/(34-Q19)+(Q19/135)+(50/(10*Q19+45)^2)-(1/200))) -> 0.15251251 | V19: =IF(B19=0," ",$K$7) -> 1.1927489 | W19: =IF(B19=0," ",U19*V19*L19) -> 13.999695 | X19: =IF(B19=0," ",0.65*K19*0.4*T19*R19) -> 30.177328 | Y19: =IF(B19=0," ",('SIVILASMA ONCESI'!O15-'SIVILASMA ONCESI'!L15)/('SIVILASMA ONCESI'!O15-'SIVILASMA ONCESI'!P15)) -> 0.92349727 | Z19: =IF(B19=0," ",IF(Q19>34,2,W19/X19)) -> 0.46391433 | AA19: =IF(B19="","",IF(OR(ISBLANK(SK!P17),SK!P17="-")," ",SK!M17/SK!P17)) -> 0.56330749 | AB19: SIVILAŞMA YOK | AC19: (PI%> 12) | AD19: =IF(B19="","",C19) -> 10.5 | AF19: =D19 -> CIM | AG19: =SK!R17 -> 18.3 | AH19: ='SIVILASMA ONCESI'!O15 -> 38.7 | AI19: =AA19 -> 0.56330749
B20: ='SIVILASMA ONCESI'!B16 -> 8 | C20: ='SIVILASMA ONCESI'!C16 -> 12 | D20: ='SIVILASMA ONCESI'!H16 -> CIM | E20: =SK!G18 -> 11 | F20: =IF(B20=0," ",$N$6) -> 1 | G20: =IF(B20=0," ",$N$7) -> 1 | H20: =IF(B20=0," ",$N$8) -> 1.1 | I20: =IF(B20=0," ",IF(AND(C20<4),0.75,IF(AND(4<=C20,C20<6),0.85,IF(AND(6<=C20,C20<10),0.95,IF(AND(10<=C20),1))))) -> 1 | J20: =IF(B20=0," ",E20*F20*G20*H20*I20) -> 12.1 | K20: =IF(B20=0," ",C20*'SIVILASMA ONCESI'!T16) -> 179.11909 | L20: =IF(B20=0," ",IF(C20<$H$11,K20,K20-(C20-$H$11)*9.81)) -> 81.019086 | M20: =IF(B20=0,"",IF(OR(D20="CIL",D20="CIH",D20="CIM"),1,IF(C20<$H$11,1,9.78*(1/L20)^0.5))) -> 1 | N20: =IF(B20=0," ",M20*J20) -> 12.1 | O20: =IF(B20=0," ",IF('SIVILASMA ONCESI'!N16<5,0,IF('SIVILASMA ONCESI'!N16>35,5,2.71828^(1.76-190/'SIVILASMA ONCESI'!N16^2)))) -> 5 | P20: =IF(B20=0," ",IF('SIVILASMA ONCESI'!N16<5,1,IF('SIVILASMA ONCESI'!N16>35,1.2,0.99+'SIVILASMA ONCESI'!N16^1.5/1000))) -> 1.2 | Q20: =IF(B20=0," ",(O20+P20*N20)) -> 19.52 | R20: =IF(B20=0," ",IF(C20<=9.15,1-0.00765*C20,IF(C20<=23,1.174-0.0267*C20,IF(C20<=30,0.744-0.008*C20,0.5)))) -> 0.8536 | S20: =IF(B20=0," ",IF(C21="",(1.5/J20),(C21-C20)/J20)) -> 0.12396694 | T20: =IF(B20=0," ",SK!$D$5) -> 0.81 | U20: =IF(B20=0," ",(1/(34-Q20)+(Q20/135)+(50/(10*Q20+45)^2)-(1/200))) -> 0.20951998 | V20: =IF(B20=0," ",$K$7) -> 1.1927489 | W20: =IF(B20=0," ",U20*V20*L20) -> 20.247052 | X20: =IF(B20=0," ",0.65*K20*0.4*T20*R20) -> 32.199909 | Y20: =IF(B20=0," ",('SIVILASMA ONCESI'!O16-'SIVILASMA ONCESI'!L16)/('SIVILASMA ONCESI'!O16-'SIVILASMA ONCESI'!P16)) -> 0.85635359 | Z20: =IF(B20=0," ",IF(Q20>34,2,W20/X20)) -> 0.62879222 | AA20: =IF(B20="","",IF(OR(ISBLANK(SK!P18),SK!P18="-")," ",SK!M18/SK!P18)) -> 0.59317585 | AB20: SIVILAŞMA YOK | AC20: (PI%> 12) | AD20: =IF(B20="","",C20) -> 12 | AF20: =D20 -> CIM | AG20: =SK!R18 -> 18.1 | AH20: ='SIVILASMA ONCESI'!O16 -> 38.1 | AI20: =AA20 -> 0.59317585
B21: ='SIVILASMA ONCESI'!B17 -> 9 | C21: ='SIVILASMA ONCESI'!C17 -> 13.5 | D21: ='SIVILASMA ONCESI'!H17 -> CIM | E21: =SK!G19 -> 35 | F21: =IF(B21=0," ",$N$6) -> 1 | G21: =IF(B21=0," ",$N$7) -> 1 | H21: =IF(B21=0," ",$N$8) -> 1.1 | I21: =IF(B21=0," ",IF(AND(C21<4),0.75,IF(AND(4<=C21,C21<6),0.85,IF(AND(6<=C21,C21<10),0.95,IF(AND(10<=C21),1))))) -> 1 | J21: =IF(B21=0," ",E21*F21*G21*H21*I21) -> 38.5 | K21: =IF(B21=0," ",C21*'SIVILASMA ONCESI'!T17) -> 202.71916 | L21: =IF(B21=0," ",IF(C21<$H$11,K21,K21-(C21-$H$11)*9.81)) -> 89.904156 | M21: =IF(B21=0,"",IF(OR(D21="CIL",D21="CIH",D21="CIM"),1,IF(C21<$H$11,1,9.78*(1/L21)^0.5))) -> 1 | N21: =IF(B21=0," ",M21*J21) -> 38.5 | O21: =IF(B21=0," ",IF('SIVILASMA ONCESI'!N17<5,0,IF('SIVILASMA ONCESI'!N17>35,5,2.71828^(1.76-190/'SIVILASMA ONCESI'!N17^2)))) -> 5 | P21: =IF(B21=0," ",IF('SIVILASMA ONCESI'!N17<5,1,IF('SIVILASMA ONCESI'!N17>35,1.2,0.99+'SIVILASMA ONCESI'!N17^1.5/1000))) -> 1.2 | Q21: =IF(B21=0," ",(O21+P21*N21)) -> 51.2 | R21: =IF(B21=0," ",IF(C21<=9.15,1-0.00765*C21,IF(C21<=23,1.174-0.0267*C21,IF(C21<=30,0.744-0.008*C21,0.5)))) -> 0.81355 | S21: =IF(B21=0," ",IF(C22="",(1.5/J21),(C22-C21)/J21)) -> 0.038961039 | T21: =IF(B21=0," ",SK!$D$5) -> 0.81 | U21: =IF(B21=0," ",(1/(34-Q21)+(Q21/135)+(50/(10*Q21+45)^2)-(1/200))) -> 0.31628089 | V21: =IF(B21=0," ",$K$7) -> 1.1927489 | W21: =IF(B21=0," ",U21*V21*L21) -> 33.915774 | X21: =IF(B21=0," ",0.65*K21*0.4*T21*R21) -> 34.732609 | Y21: =IF(B21=0," ",('SIVILASMA ONCESI'!O17-'SIVILASMA ONCESI'!L17)/('SIVILASMA ONCESI'!O17-'SIVILASMA ONCESI'!P17)) -> 0.81094527 | Z21: =IF(B21=0," ",IF(Q21>34,2,W21/X21)) -> 2 | AA21: =IF(B21="","",IF(OR(ISBLANK(SK!P19),SK!P19="-")," ",SK!M19/SK!P19)) -> 0.58734177 | AB21: SIVILAŞMA YOK | AC21: GS > 1,1 | AD21: =IF(B21="","",C21) -> 13.5 | AF21: =D21 -> CIM | AG21: =SK!R19 -> 20.1 | AH21: ='SIVILASMA ONCESI'!O17 -> 39.5 | AI21: =AA21 -> 0.58734177
B22: ='SIVILASMA ONCESI'!B18 -> 10 | C22: ='SIVILASMA ONCESI'!C18 -> 15 | D22: ='SIVILASMA ONCESI'!H18 -> CIM | E22: =SK!G20 -> 9 | F22: =IF(B22=0," ",$N$6) -> 1 | G22: =IF(B22=0," ",$N$7) -> 1 | H22: =IF(B22=0," ",$N$8) -> 1.1 | I22: =IF(B22=0," ",IF(AND(C22<4),0.75,IF(AND(4<=C22,C22<6),0.85,IF(AND(6<=C22,C22<10),0.95,IF(AND(10<=C22),1))))) -> 1 | J22: =IF(B22=0," ",E22*F22*G22*H22*I22) -> 9.9 | K22: =IF(B22=0," ",C22*'SIVILASMA ONCESI'!T18) -> 225.30612 | L22: =IF(B22=0," ",IF(C22<$H$11,K22,K22-(C22-$H$11)*9.81)) -> 97.776122 | M22: =IF(B22=0,"",IF(OR(D22="CIL",D22="CIH",D22="CIM"),1,IF(C22<$H$11,1,9.78*(1/L22)^0.5))) -> 1 | N22: =IF(B22=0," ",M22*J22) -> 9.9 | O22: =IF(B22=0," ",IF('SIVILASMA ONCESI'!N18<5,0,IF('SIVILASMA ONCESI'!N18>35,5,2.71828^(1.76-190/'SIVILASMA ONCESI'!N18^2)))) -> 5 | P22: =IF(B22=0," ",IF('SIVILASMA ONCESI'!N18<5,1,IF('SIVILASMA ONCESI'!N18>35,1.2,0.99+'SIVILASMA ONCESI'!N18^1.5/1000))) -> 1.2 | Q22: =IF(B22=0," ",(O22+P22*N22)) -> 16.88 | R22: =IF(B22=0," ",IF(C22<=9.15,1-0.00765*C22,IF(C22<=23,1.174-0.0267*C22,IF(C22<=30,0.744-0.008*C22,0.5)))) -> 0.7735 | S22: =IF(B22=0," ",IF(C23="",(1.5/J22),(C23-C22)/J22)) -> 0.15151515 | T22: =IF(B22=0," ",SK!$D$5) -> 0.81 | U22: =IF(B22=0," ",(1/(34-Q22)+(Q22/135)+(50/(10*Q22+45)^2)-(1/200))) -> 0.17954209 | V22: =IF(B22=0," ",$K$7) -> 1.1927489 | W22: =IF(B22=0," ",U22*V22*L22) -> 20.938623 | X22: =IF(B22=0," ",0.65*K22*0.4*T22*R22) -> 36.702165 | Y22: =IF(B22=0," ",('SIVILASMA ONCESI'!O18-'SIVILASMA ONCESI'!L18)/('SIVILASMA ONCESI'!O18-'SIVILASMA ONCESI'!P18)) -> 0.88202247 | Z22: =IF(B22=0," ",IF(Q22>34,2,W22/X22)) -> 0.57050103 | AA22: =IF(B22="","",IF(OR(ISBLANK(SK!P20),SK!P20="-")," ",SK!M20/SK!P20)) -> 0.58900524 | AB22: SIVILAŞMA YOK | AC22: (PI%> 12) | AD22: =IF(B22="","",C22) -> 15 | AF22: =D22 -> CIM | AG22: =SK!R20 -> 17.8 | AH22: ='SIVILASMA ONCESI'!O18 -> 38.2 | AI22: =AA22 -> 0.58900524
B23: ='SIVILASMA ONCESI'!B19 -> 11 | C23: ='SIVILASMA ONCESI'!C19 -> 16.5 | D23: ='SIVILASMA ONCESI'!H19 -> CIM | E23: =SK!G21 -> 9 | F23: =IF(B23=0," ",$N$6) -> 1 | G23: =IF(B23=0," ",$N$7) -> 1 | H23: =IF(B23=0," ",$N$8) -> 1.1 | I23: =IF(B23=0," ",IF(AND(C23<4),0.75,IF(AND(4<=C23,C23<6),0.85,IF(AND(6<=C23,C23<10),0.95,IF(AND(10<=C23),1))))) -> 1 | J23: =IF(B23=0," ",E23*F23*G23*H23*I23) -> 9.9 | K23: =IF(B23=0," ",C23*'SIVILASMA ONCESI'!T19) -> 249.10714 | L23: =IF(B23=0," ",IF(C23<$H$11,K23,K23-(C23-$H$11)*9.81)) -> 106.86214 | M23: =IF(B23=0,"",IF(OR(D23="CIL",D23="CIH",D23="CIM"),1,IF(C23<$H$11,1,9.78*(1/L23)^0.5))) -> 1 | N23: =IF(B23=0," ",M23*J23) -> 9.9 | O23: =IF(B23=0," ",IF('SIVILASMA ONCESI'!N19<5,0,IF('SIVILASMA ONCESI'!N19>35,5,2.71828^(1.76-190/'SIVILASMA ONCESI'!N19^2)))) -> 5 | P23: =IF(B23=0," ",IF('SIVILASMA ONCESI'!N19<5,1,IF('SIVILASMA ONCESI'!N19>35,1.2,0.99+'SIVILASMA ONCESI'!N19^1.5/1000))) -> 1.2 | Q23: =IF(B23=0," ",(O23+P23*N23)) -> 16.88 | R23: =IF(B23=0," ",IF(C23<=9.15,1-0.00765*C23,IF(C23<=23,1.174-0.0267*C23,IF(C23<=30,0.744-0.008*C23,0.5)))) -> 0.73345 | S23: =IF(B23=0," ",IF(C24="",(1.5/J23),(C24-C23)/J23)) -> 0.15151515 | T23: =IF(B23=0," ",SK!$D$5) -> 0.81 | U23: =IF(B23=0," ",(1/(34-Q23)+(Q23/135)+(50/(10*Q23+45)^2)-(1/200))) -> 0.17954209 | V23: =IF(B23=0," ",$K$7) -> 1.1927489 | W23: =IF(B23=0," ",U23*V23*L23) -> 22.884382 | X23: =IF(B23=0," ",0.65*K23*0.4*T23*R23) -> 38.478228 | Y23: =IF(B23=0," ",('SIVILASMA ONCESI'!O19-'SIVILASMA ONCESI'!L19)/('SIVILASMA ONCESI'!O19-'SIVILASMA ONCESI'!P19)) -> 0.8241206 | Z23: =IF(B23=0," ",IF(Q23>34,2,W23/X23)) -> 0.59473586 | AA23: =IF(B23="","",IF(OR(ISBLANK(SK!P21),SK!P21="-")," ",SK!M21/SK!P21)) -> 0.58585859 | AB23: SIVILAŞMA YOK | AC23: GS > 1,1 | AD23: =IF(B23="","",C23) -> 16.5 | AF23: =D23 -> CIM | AG23: =SK!R21 -> 19.9 | AH23: ='SIVILASMA ONCESI'!O19 -> 39.6 | AI23: =AA23 -> 0.58585859
B24: ='SIVILASMA ONCESI'!B20 -> 12 | C24: ='SIVILASMA ONCESI'!C20 -> 18 | D24: ='SIVILASMA ONCESI'!H20 -> CIM | E24: =SK!G22 -> 22 | F24: =IF(B24=0," ",$N$6) -> 1 | G24: =IF(B24=0," ",$N$7) -> 1 | H24: =IF(B24=0," ",$N$8) -> 1.1 | I24: =IF(B24=0," ",IF(AND(C24<4),0.75,IF(AND(4<=C24,C24<6),0.85,IF(AND(6<=C24,C24<10),0.95,IF(AND(10<=C24),1))))) -> 1 | J24: =IF(B24=0," ",E24*F24*G24*H24*I24) -> 24.2 | K24: =IF(B24=0," ",C24*'SIVILASMA ONCESI'!T20) -> 275 | L24: =IF(B24=0," ",IF(C24<$H$11,K24,K24-(C24-$H$11)*9.81)) -> 118.04 | M24: =IF(B24=0,"",IF(OR(D24="CIL",D24="CIH",D24="CIM"),1,IF(C24<$H$11,1,9.78*(1/L24)^0.5))) -> 1 | N24: =IF(B24=0," ",M24*J24) -> 24.2 | O24: =IF(B24=0," ",IF('SIVILASMA ONCESI'!N20<5,0,IF('SIVILASMA ONCESI'!N20>35,5,2.71828^(1.76-190/'SIVILASMA ONCESI'!N20^2)))) -> 5 | P24: =IF(B24=0," ",IF('SIVILASMA ONCESI'!N20<5,1,IF('SIVILASMA ONCESI'!N20>35,1.2,0.99+'SIVILASMA ONCESI'!N20^1.5/1000))) -> 1.2 | Q24: =IF(B24=0," ",(O24+P24*N24)) -> 34.04 | R24: =IF(B24=0," ",IF(C24<=9.15,1-0.00765*C24,IF(C24<=23,1.174-0.0267*C24,IF(C24<=30,0.744-0.008*C24,0.5)))) -> 0.6934 | S24: =IF(B24=0," ",IF(C25="",(1.5/J24),(C25-C24)/J24)) -> 0.061983471 | T24: =IF(B24=0," ",SK!$D$5) -> 0.81 | U24: =IF(B24=0," ",(1/(34-Q24)+(Q24/135)+(50/(10*Q24+45)^2)-(1/200))) -> -24.752515 | V24: =IF(B24=0," ",$K$7) -> 1.1927489 | W24: =IF(B24=0," ",U24*V24*L24) -> -3484.9581 | X24: =IF(B24=0," ",0.65*K24*0.4*T24*R24) -> 40.158261 | Y24: =IF(B24=0," ",('SIVILASMA ONCESI'!O20-'SIVILASMA ONCESI'!L20)/('SIVILASMA ONCESI'!O20-'SIVILASMA ONCESI'!P20)) -> 0.88700565 | Z24: =IF(B24=0," ",IF(Q24>34,2,W24/X24)) -> 2 | AA24: =IF(B24="","",IF(OR(ISBLANK(SK!P22),SK!P22="-")," ",SK!M22/SK!P22)) -> 0.58792651 | AB24: SIVILAŞMA YOK | AC24: GS > 1,1 | AD24: =IF(B24="","",C24) -> 18 | AF24: =D24 -> CIM | AG24: =SK!R22 -> 17.7 | AH24: ='SIVILASMA ONCESI'!O20 -> 38.1 | AI24: =AA24 -> 0.58792651
B25: ='SIVILASMA ONCESI'!B21 -> 13 | C25: ='SIVILASMA ONCESI'!C21 -> 19.5 | D25: ='SIVILASMA ONCESI'!H21 -> CIM | E25: =SK!G23 -> 25 | F25: =IF(B25=0," ",$N$6) -> 1 | G25: =IF(B25=0," ",$N$7) -> 1 | H25: =IF(B25=0," ",$N$8) -> 1.1 | I25: =IF(B25=0," ",IF(AND(C25<4),0.75,IF(AND(4<=C25,C25<6),0.85,IF(AND(6<=C25,C25<10),0.95,IF(AND(10<=C25),1))))) -> 1 | J25: =IF(B25=0," ",E25*F25*G25*H25*I25) -> 27.5 | K25: =IF(B25=0," ",C25*'SIVILASMA ONCESI'!T21) -> 292.10526 | L25: =IF(B25=0," ",IF(C25<$H$11,K25,K25-(C25-$H$11)*9.81)) -> 120.43026 | M25: =IF(B25=0,"",IF(OR(D25="CIL",D25="CIH",D25="CIM"),1,IF(C25<$H$11,1,9.78*(1/L25)^0.5))) -> 1 | N25: =IF(B25=0," ",M25*J25) -> 27.5 | O25: =IF(B25=0," ",IF('SIVILASMA ONCESI'!N21<5,0,IF('SIVILASMA ONCESI'!N21>35,5,2.71828^(1.76-190/'SIVILASMA ONCESI'!N21^2)))) -> 5 | P25: =IF(B25=0," ",IF('SIVILASMA ONCESI'!N21<5,1,IF('SIVILASMA ONCESI'!N21>35,1.2,0.99+'SIVILASMA ONCESI'!N21^1.5/1000))) -> 1.2 | Q25: =IF(B25=0," ",(O25+P25*N25)) -> 38 | R25: =IF(B25=0," ",IF(C25<=9.15,1-0.00765*C25,IF(C25<=23,1.174-0.0267*C25,IF(C25<=30,0.744-0.008*C25,0.5)))) -> 0.65335 | S25: =IF(B25=0," ",IF(C26="",(1.5/J25),(C26-C25)/J25)) -> 0.054545455 | T25: =IF(B25=0," ",SK!$D$5) -> 0.81 | U25: =IF(B25=0," ",(1/(34-Q25)+(Q25/135)+(50/(10*Q25+45)^2)-(1/200))) -> 0.026758298 | V25: =IF(B25=0," ",$K$7) -> 1.1927489 | W25: =IF(B25=0," ",U25*V25*L25) -> 3.8436439 | X25: =IF(B25=0," ",0.65*K25*0.4*T25*R25) -> 40.192373 | Y25: =IF(B25=0," ",('SIVILASMA ONCESI'!O21-'SIVILASMA ONCESI'!L21)/('SIVILASMA ONCESI'!O21-'SIVILASMA ONCESI'!P21)) -> 0.81871345 | Z25: =IF(B25=0," ",IF(Q25>34,2,W25/X25)) -> 2 | AA25: =IF(B25="","",IF(OR(ISBLANK(SK!P23),SK!P23="-")," ",SK!M23/SK!P23)) -> 0.62666667 | AB25: SIVILAŞMA YOK | AC25: GS > 1,1 | AD25: =IF(B25="","",C25) -> 19.5 | AF25: =D25 -> CIM | AG25: =SK!R23 -> 17.1 | AH25: ='SIVILASMA ONCESI'!O21 -> 37.5 | AI25: =AA25 -> 0.62666667
B26: ='SIVILASMA ONCESI'!B22 -> 0 | C26: ='SIVILASMA ONCESI'!C22 | D26: ='SIVILASMA ONCESI'!H22 -> 0 | E26: =SK!G24 | F26: =IF(B26=0," ",$N$6) | G26: =IF(B26=0," ",$N$7) | H26: =IF(B26=0," ",$N$8) | I26: =IF(B26=0," ",IF(AND(C26<4),0.75,IF(AND(4<=C26,C26<6),0.85,IF(AND(6<=C26,C26<10),0.95,IF(AND(10<=C26),1))))) | J26: =IF(B26=0," ",E26*F26*G26*H26*I26) | K26: =IF(B26=0," ",C26*'SIVILASMA ONCESI'!T22) | L26: =IF(B26=0," ",IF(C26<$H$11,K26,K26-(C26-$H$11)*9.81)) | M26: =IF(B26=0,"",IF(OR(D26="CIL",D26="CIH",D26="CIM"),1,IF(C26<$H$11,1,9.78*(1/L26)^0.5))) | N26: =IF(B26=0," ",M26*J26) | O26: =IF(B26=0," ",IF('SIVILASMA ONCESI'!N22<5,0,IF('SIVILASMA ONCESI'!N22>35,5,2.71828^(1.76-190/'SIVILASMA ONCESI'!N22^2)))) | P26: =IF(B26=0," ",IF('SIVILASMA ONCESI'!N22<5,1,IF('SIVILASMA ONCESI'!N22>35,1.2,0.99+'SIVILASMA ONCESI'!N22^1.5/1000))) | Q26: =IF(B26=0," ",(O26+P26*N26)) | R26: =IF(B26=0," ",IF(C26<=9.15,1-0.00765*C26,IF(C26<=23,1.174-0.0267*C26,IF(C26<=30,0.744-0.008*C26,0.5)))) | S26: =IF(B26=0," ",IF(C27="",(1.5/J26),(C27-C26)/J26)) | T26: =IF(B26=0," ",SK!$D$5) | U26: =IF(B26=0," ",(1/(34-Q26)+(Q26/135)+(50/(10*Q26+45)^2)-(1/200))) | V26: =IF(B26=0," ",$K$7) | W26: =IF(B26=0," ",U26*V26*L26) | X26: =IF(B26=0," ",0.65*K26*0.4*T26*R26) | Y26: =IF(B26=0," ",('SIVILASMA ONCESI'!O22-'SIVILASMA ONCESI'!L22)/('SIVILASMA ONCESI'!O22-'SIVILASMA ONCESI'!P22)) | Z26: =IF(B26=0," ",IF(Q26>34,2,W26/X26)) | AA26: =IF(B26="","",IF(OR(ISBLANK(SK!P24),SK!P24="-")," ",SK!M24/SK!P24)) | AD26: =IF(B26="","",C26) | AF26: =D26 -> 0 | AG26: =SK!R24 | AH26: ='SIVILASMA ONCESI'!O22 -> 0 | AI26: =AA26
B27: ='SIVILASMA ONCESI'!B23 -> 0 | C27: ='SIVILASMA ONCESI'!C23 -> 0 | D27: ='SIVILASMA ONCESI'!H23 -> 0 | E27: =SK!G25 | F27: =IF(B27=0," ",$N$6) | G27: =IF(B27=0," ",$N$7) | H27: =IF(B27=0," ",$N$8) | I27: =IF(B27=0," ",IF(AND(C27<4),0.75,IF(AND(4<=C27,C27<6),0.85,IF(AND(6<=C27,C27<10),0.95,IF(AND(10<=C27),1))))) | J27: =IF(B27=0," ",E27*F27*G27*H27*I27) | K27: =IF(B27=0," ",C27*'SIVILASMA ONCESI'!T23) | L27: =IF(B27=0," ",IF(C27<$H$11,K27,K27-(C27-$H$11)*9.81)) | M27: =IF(B27=0,"",IF(OR(D27="CIL",D27="CIH",D27="CIM"),1,IF(C27<$H$11,1,9.78*(1/L27)^0.5))) | N27: =IF(B27=0," ",M27*J27) | O27: =IF(B27=0," ",IF('SIVILASMA ONCESI'!N23<5,0,IF('SIVILASMA ONCESI'!N23>35,5,2.71828^(1.76-190/'SIVILASMA ONCESI'!N23^2)))) | P27: =IF(B27=0," ",IF('SIVILASMA ONCESI'!N23<5,1,IF('SIVILASMA ONCESI'!N23>35,1.2,0.99+'SIVILASMA ONCESI'!N23^1.5/1000))) | Q27: =IF(B27=0," ",(O27+P27*N27)) | R27: =IF(B27=0," ",IF(C27<=9.15,1-0.00765*C27,IF(C27<=23,1.174-0.0267*C27,IF(C27<=30,0.744-0.008*C27,0.5)))) | S27: =IF(B27=0," ",IF(C28="",(1.5/J27),(C28-C27)/J27)) | T27: =IF(B27=0," ",SK!$D$5) | U27: =IF(B27=0," ",(1/(34-Q27)+(Q27/135)+(50/(10*Q27+45)^2)-(1/200))) | V27: =IF(B27=0," ",$K$7) | W27: =IF(B27=0," ",U27*V27*L27) | X27: =IF(B27=0," ",0.65*K27*0.4*T27*R27) | Y27: =IF(B27=0," ",('SIVILASMA ONCESI'!O23-'SIVILASMA ONCESI'!L23)/('SIVILASMA ONCESI'!O23-'SIVILASMA ONCESI'!P23)) | Z27: =IF(B27=0," ",IF(Q27>34,2,W27/X27)) | AA27: =IF(B27="","",IF(OR(ISBLANK(SK!P25),SK!P25="-")," ",SK!M25/SK!P25)) | AD27: =IF(B27="","",C27) -> 0 | AF27: =D27 -> 0 | AG27: =SK!R25 | AH27: ='SIVILASMA ONCESI'!O23 -> 0 | AI27: =AA27
B28: ='SIVILASMA ONCESI'!B24 -> 0 | C28: ='SIVILASMA ONCESI'!C24 -> 0 | D28: ='SIVILASMA ONCESI'!H24 -> 0 | E28: =SK!G26 | F28: =IF(B28=0," ",$N$6) | G28: =IF(B28=0," ",$N$7) | H28: =IF(B28=0," ",$N$8) | I28: =IF(B28=0," ",IF(AND(C28<4),0.75,IF(AND(4<=C28,C28<6),0.85,IF(AND(6<=C28,C28<10),0.95,IF(AND(10<=C28),1))))) | J28: =IF(B28=0," ",E28*F28*G28*H28*I28) | K28: =IF(B28=0," ",C28*'SIVILASMA ONCESI'!T24) | L28: =IF(B28=0," ",IF(C28<$H$11,K28,K28-(C28-$H$11)*9.81)) | M28: =IF(B28=0,"",IF(OR(D28="CIL",D28="CIH",D28="CIM"),1,IF(C28<$H$11,1,9.78*(1/L28)^0.5))) | N28: =IF(B28=0," ",M28*J28) | O28: =IF(B28=0," ",IF('SIVILASMA ONCESI'!N24<5,0,IF('SIVILASMA ONCESI'!N24>35,5,2.71828^(1.76-190/'SIVILASMA ONCESI'!N24^2)))) | P28: =IF(B28=0," ",IF('SIVILASMA ONCESI'!N24<5,1,IF('SIVILASMA ONCESI'!N24>35,1.2,0.99+'SIVILASMA ONCESI'!N24^1.5/1000))) | Q28: =IF(B28=0," ",(O28+P28*N28)) | R28: =IF(B28=0," ",IF(C28<=9.15,1-0.00765*C28,IF(C28<=23,1.174-0.0267*C28,IF(C28<=30,0.744-0.008*C28,0.5)))) | S28: =IF(B28=0," ",IF(C29="",(1.5/J28),(C29-C28)/J28)) | T28: =IF(B28=0," ",SK!$D$5) | U28: =IF(B28=0," ",(1/(34-Q28)+(Q28/135)+(50/(10*Q28+45)^2)-(1/200))) | V28: =IF(B28=0," ",$K$7) | W28: =IF(B28=0," ",U28*V28*L28) | X28: =IF(B28=0," ",0.65*K28*0.4*T28*R28) | Y28: =IF(B28=0," ",('SIVILASMA ONCESI'!O24-'SIVILASMA ONCESI'!L24)/('SIVILASMA ONCESI'!O24-'SIVILASMA ONCESI'!P24)) | Z28: =IF(B28=0," ",IF(Q28>34,2,W28/X28)) | AA28: =IF(B28="","",IF(OR(ISBLANK(SK!P26),SK!P26="-")," ",SK!M26/SK!P26)) | AD28: =IF(B28="","",C28) -> 0 | AF28: =D28 -> 0 | AG28: =SK!R26 | AH28: ='SIVILASMA ONCESI'!O24 -> 0 | AI28: =AA28
B29: ='SIVILASMA ONCESI'!B25 -> 0 | C29: ='SIVILASMA ONCESI'!C25 -> 0 | D29: ='SIVILASMA ONCESI'!H25 -> 0 | E29: =SK!G27 | F29: =IF(B29=0," ",$N$6) | G29: =IF(B29=0," ",$N$7) | H29: =IF(B29=0," ",$N$8) | I29: =IF(B29=0," ",IF(AND(C29<4),0.75,IF(AND(4<=C29,C29<6),0.85,IF(AND(6<=C29,C29<10),0.95,IF(AND(10<=C29),1))))) | J29: =IF(B29=0," ",E29*F29*G29*H29*I29) | K29: =IF(B29=0," ",C29*'SIVILASMA ONCESI'!T25) | L29: =IF(B29=0," ",IF(C29<$H$11,K29,K29-(C29-$H$11)*9.81)) | M29: =IF(B29=0,"",IF(OR(D29="CIL",D29="CIH",D29="CIM"),1,IF(C29<$H$11,1,9.78*(1/L29)^0.5))) | N29: =IF(B29=0," ",M29*J29) | O29: =IF(B29=0," ",IF('SIVILASMA ONCESI'!N25<5,0,IF('SIVILASMA ONCESI'!N25>35,5,2.71828^(1.76-190/'SIVILASMA ONCESI'!N25^2)))) | P29: =IF(B29=0," ",IF('SIVILASMA ONCESI'!N25<5,1,IF('SIVILASMA ONCESI'!N25>35,1.2,0.99+'SIVILASMA ONCESI'!N25^1.5/1000))) | Q29: =IF(B29=0," ",(O29+P29*N29)) | R29: =IF(B29=0," ",IF(C29<=9.15,1-0.00765*C29,IF(C29<=23,1.174-0.0267*C29,IF(C29<=30,0.744-0.008*C29,0.5)))) | S29: =IF(B29=0," ",IF(C30="",(1.5/J29),(C30-C29)/J29)) | T29: =IF(B29=0," ",SK!$D$5) | U29: =IF(B29=0," ",(1/(34-Q29)+(Q29/135)+(50/(10*Q29+45)^2)-(1/200))) | V29: =IF(B29=0," ",$K$7) | W29: =IF(B29=0," ",U29*V29*L29) | X29: =IF(B29=0," ",0.65*K29*0.4*T29*R29) | Y29: =IF(B29=0," ",('SIVILASMA ONCESI'!O25-'SIVILASMA ONCESI'!L25)/('SIVILASMA ONCESI'!O25-'SIVILASMA ONCESI'!P25)) | Z29: =IF(B29=0," ",IF(Q29>34,2,W29/X29)) | AA29: =IF(B29="","",IF(OR(ISBLANK(SK!P27),SK!P27="-")," ",SK!M27/SK!P27)) | AD29: =IF(B29="","",C29) -> 0 | AF29: =D29 -> 0 | AG29: =SK!R27 | AH29: ='SIVILASMA ONCESI'!O25 -> 0 | AI29: =AA29
B30: ='SIVILASMA ONCESI'!B26 -> 0 | C30: ='SIVILASMA ONCESI'!C26 -> 0 | D30: ='SIVILASMA ONCESI'!H26 -> 0 | E30: =SK!G28 | F30: =IF(B30=0," ",$N$6) | G30: =IF(B30=0," ",$N$7) | H30: =IF(B30=0," ",$N$8) | I30: =IF(B30=0," ",IF(AND(C30<4),0.75,IF(AND(4<=C30,C30<6),0.85,IF(AND(6<=C30,C30<10),0.95,IF(AND(10<=C30),1))))) | J30: =IF(B30=0," ",E30*F30*G30*H30*I30) | K30: =IF(B30=0," ",C30*'SIVILASMA ONCESI'!T26) | L30: =IF(B30=0," ",IF(C30<$H$11,K30,K30-(C30-$H$11)*9.81)) | M30: =IF(B30=0,"",IF(OR(D30="CIL",D30="CIH",D30="CIM"),1,IF(C30<$H$11,1,9.78*(1/L30)^0.5))) | N30: =IF(B30=0," ",M30*J30) | O30: =IF(B30=0," ",IF('SIVILASMA ONCESI'!N26<5,0,IF('SIVILASMA ONCESI'!N26>35,5,2.71828^(1.76-190/'SIVILASMA ONCESI'!N26^2)))) | P30: =IF(B30=0," ",IF('SIVILASMA ONCESI'!N26<5,1,IF('SIVILASMA ONCESI'!N26>35,1.2,0.99+'SIVILASMA ONCESI'!N26^1.5/1000))) | Q30: =IF(B30=0," ",(O30+P30*N30)) | R30: =IF(B30=0," ",IF(C30<=9.15,1-0.00765*C30,IF(C30<=23,1.174-0.0267*C30,IF(C30<=30,0.744-0.008*C30,0.5)))) | S30: =IF(B30=0," ",IF(C31="",(1.5/J30),(C31-C30)/J30)) | T30: =IF(B30=0," ",SK!$D$5) | U30: =IF(B30=0," ",(1/(34-Q30)+(Q30/135)+(50/(10*Q30+45)^2)-(1/200))) | V30: =IF(B30=0," ",$K$7) | W30: =IF(B30=0," ",U30*V30*L30) | X30: =IF(B30=0," ",0.65*K30*0.4*T30*R30) | Y30: =IF(B30=0," ",('SIVILASMA ONCESI'!O26-'SIVILASMA ONCESI'!L26)/('SIVILASMA ONCESI'!O26-'SIVILASMA ONCESI'!P26)) | Z30: =IF(B30=0," ",IF(Q30>34,2,W30/X30)) | AA30: =IF(B30="","",IF(OR(ISBLANK(SK!P28),SK!P28="-")," ",SK!M28/SK!P28)) | AD30: =IF(B30="","",C30) -> 0 | AF30: =D30 -> 0 | AG30: =SK!R28 | AH30: ='SIVILASMA ONCESI'!O26 -> 0 | AI30: =AA30
B31: ='SIVILASMA ONCESI'!B27 -> 0 | C31: ='SIVILASMA ONCESI'!C27 -> 0 | D31: ='SIVILASMA ONCESI'!H27 -> 0 | E31: =SK!G29 | F31: =IF(B31=0," ",$N$6) | G31: =IF(B31=0," ",$N$7) | H31: =IF(B31=0," ",$N$8) | I31: =IF(B31=0," ",IF(AND(C31<4),0.75,IF(AND(4<=C31,C31<6),0.85,IF(AND(6<=C31,C31<10),0.95,IF(AND(10<=C31),1))))) | J31: =IF(B31=0," ",E31*F31*G31*H31*I31) | K31: =IF(B31=0," ",C31*'SIVILASMA ONCESI'!T27) | L31: =IF(B31=0," ",IF(C31<$H$11,K31,K31-(C31-$H$11)*9.81)) | M31: =IF(B31=0,"",IF(OR(D31="CIL",D31="CIH",D31="CIM"),1,IF(C31<$H$11,1,9.78*(1/L31)^0.5))) | N31: =IF(B31=0," ",M31*J31) | O31: =IF(B31=0," ",IF('SIVILASMA ONCESI'!N27<5,0,IF('SIVILASMA ONCESI'!N27>35,5,2.71828^(1.76-190/'SIVILASMA ONCESI'!N27^2)))) | P31: =IF(B31=0," ",IF('SIVILASMA ONCESI'!N27<5,1,IF('SIVILASMA ONCESI'!N27>35,1.2,0.99+'SIVILASMA ONCESI'!N27^1.5/1000))) | Q31: =IF(B31=0," ",(O31+P31*N31)) | R31: =IF(B31=0," ",IF(C31<=9.15,1-0.00765*C31,IF(C31<=23,1.174-0.0267*C31,IF(C31<=30,0.744-0.008*C31,0.5)))) | S31: =IF(B31=0," ",IF(C32="",(1.5/J31),(C32-C31)/J31)) | T31: =IF(B31=0," ",SK!$D$5) | U31: =IF(B31=0," ",(1/(34-Q31)+(Q31/135)+(50/(10*Q31+45)^2)-(1/200))) | V31: =IF(B31=0," ",$K$7) | W31: =IF(B31=0," ",U31*V31*L31) | X31: =IF(B31=0," ",0.65*K31*0.4*T31*R31) | Y31: =IF(B31=0," ",('SIVILASMA ONCESI'!O27-'SIVILASMA ONCESI'!L27)/('SIVILASMA ONCESI'!O27-'SIVILASMA ONCESI'!P27)) | Z31: =IF(B31=0," ",IF(Q31>34,2,W31/X31)) | AA31: =IF(B31="","",IF(OR(ISBLANK(SK!P29),SK!P29="-")," ",SK!M29/SK!P29)) | AD31: =IF(B31="","",C31) -> 0 | AF31: =D31 -> 0 | AG31: =SK!R29 | AH31: ='SIVILASMA ONCESI'!O27 -> 0 | AI31: =AA31
D33: ORT= | E33: =AVERAGE(E13:E31) -> 15.153846 | I33: ORT= | J33: =AVERAGE(J13:J31) -> 15.742692 | M33: ORT= | N33: =AVERAGE(N13:N31) -> 16.285057 | P33: ORT= | Q33: =AVERAGE(Q13:Q31) -> 24.542069 | R33: TOPLAM | S33: =SUM(S13:S31) -> 1.6843654
S34: =20/S33 -> 11.873908
B35: CN = killi zeminlerde 1 alınmıştır. | G35: N1(60)f >34 OLAN ZEMİNLERDE GS=2 OLARAK SIVILAŞMAZ KABUL EDİLİR.
B36: CN = YASS üstü 1 alınmıştır.
B40: Kriter / Yöntem | E40: wn​/LL Şartı | I40: Diğer Koşullar | M40: Sonuç
B41: Çin Kriteri (Wang, 1979) | E41: WN​/LL >=0,9 | I41: İnce Dane (< 0.005 mm} %15 ,LL < 35 | M41: Sıvılaşabilir
B42: Seed et al. (2003) | E42: WN​/LL >=0,85 | I42: PI < 12, LL < 37 | M42: Sıvılaşmaya Hassas Zone A
B43: Boulanger & Idriss (2006) | E43: WN​/LL >=0,80-0,85 | I43: PI < 7 (Kumlu davranış) | M43: Sıvılaşabilir (Kumlara benzer tetiklenme)
B46: Ic ≤ 0,5 ---- camur balcık kıvamında zemin , depremde mukavemet kaybına uğrar.
B47: Ic≥0,75-1,00 --- oyun hamuru veya daha sert kıvamda , depremde mukavemet kaybı yaşamaz.

Sheet JET SONRASI-1
D2: SV(DÜŞEY)(m) | E2: SH(YATAY)(m)
B3: KOLON ARALIĞI | D3: 2 | E3: 2 | H3: JET GROUT KOLONLARI KESME GÜVENLİĞİ
B4: KOLON ÇAPI | D4: 0.6 | E4: m | F4: JET BETON
B5: KOLON ALANI | D5: =PI()*D4*D4/4 -> 0.28274334 | E5: m2 | F5: 5 | G5: mPa
B6: =SK!B8 -> A BLOK SK-1 | H6: NOT:KONTROLLER JET GROUT KOLONLARI DERİNLİĞİNE KADAR SAĞLAMAK ZORUNDA
B8: NUMUNE NO | C8: Derinlik (m) | D8: Y.A.S.S (m) | E8: FJG | F8: EJG | G8: POİSSON | H8: GJG | I8: VS | J8: γ t/m3 (Doğal Birim Hacim Ağırlık ) | K8: GS | L8: GR | M8: BİRİM ALAN (SV x SH) | N8: aR | O8: 1-aR | P8: 1/GR | Q8: SR | R8: τ Deprem | S8: Vİ | T8: VİJ | U8: KESME KONTROL | V8: AÇIKLAMA | W8: Derinlik (m)
B9: =IF('SIVILASMA ONCESI'!B9="","",'SIVILASMA ONCESI'!B9) -> 1 | C9: =IF(B9="","",'SIVILASMA ONCESI'!C9) -> 1.5 | D9: =IF(B9=0," ",'SIVILASMA ONCESI'!$H$7) -> 2 | E9: =IF(B9=0," ",$F$5) -> 5 | F9: =IF(B9=0," ",(4730*SQRT(E9/2))) -> 7478.7867 | G9: =IF(B9=0," ",0.5) -> 0.5 | H9: =IF(B9=0," ",F9/(2*(1+G9))) -> 2492.9289 | I9: =IF(B9=0," ",'SIVILASMA ONCESI'!$D$2) -> 134.7 | J9: =IF(B9=0," ",'SIVILASMA ONCESI'!R9) -> 1.74 | K9: =IF(B9=0," ",J9*I9*I9) -> 31570.717 | L9: =IF(B9=0," ",(H9/K9)*1000) -> 78.963329 | M9: =IF(B9=0," ",$D$3*$E$3) -> 4 | N9: =IF(B9=0," ",$D$5/M9) -> 0.070685835 | O9: =IF(B9=0," ",1-N9) -> 0.92931417 | P9: =IF(B9=0," ",1/L9) -> 0.012664106 | Q9: =IF(B9=0," ",(P9*(1/(N9+O9*P9)))) -> 0.15358853 | R9: =IF(B9="","",SIVILASMA!X13) -> 4.5583774 | S9: =IF(B9=0," ",(R9*(1-Q9)*M9)) -> 15.433052 | T9: =IF(B9=0," ",(1000*0.3*$D$5*(E9/2)^0.5)) -> 134.11694 | U9: =IF(B9=0," ",IF(S9<T9,1,0)) -> 1 | V9: =IF(B9="","",IF(U9=1,"KESME GÜVENLİĞİ SAĞLANMIŞTIR.","JET KOLONLARININ ÇAPINI , ARALIĞINI YA DA BETON DAYANIMINI ARTIRIN.")) -> KESME GÜVENLİĞİ SAĞLANMIŞTIR. | W9: =C9 -> 1.5
B10: =IF('SIVILASMA ONCESI'!B10="","",'SIVILASMA ONCESI'!B10) -> 2 | C10: =IF(B10="","",'SIVILASMA ONCESI'!C10) -> 3 | D10: =IF(B10=0," ",'SIVILASMA ONCESI'!$H$7) -> 2 | E10: =IF(B10=0," ",$F$5) -> 5 | F10: =IF(B10=0," ",(4730*SQRT(E10/2))) -> 7478.7867 | G10: =IF(B10=0," ",0.5) -> 0.5 | H10: =IF(B10=0," ",F10/(2*(1+G10))) -> 2492.9289 | I10: =IF(B10=0," ",'SIVILASMA ONCESI'!$D$2) -> 134.7 | J10: =IF(B10=0," ",'SIVILASMA ONCESI'!R10) -> 1.85 | K10: =IF(B10=0," ",J10*I10*I10) -> 33566.566 | L10: =IF(B10=0," ",(H10/K10)*1000) -> 74.268212 | M10: =IF(B10=0," ",$D$3*$E$3) -> 4 | N10: =IF(B10=0," ",$D$5/M10) -> 0.070685835 | O10: =IF(B10=0," ",1-N10) -> 0.92931417 | P10: =IF(B10=0," ",1/L10) -> 0.013464711 | Q10: =IF(B10=0," ",(P10*(1/(N10+O10*P10)))) -> 0.16183784 | R10: =IF(B10="","",SIVILASMA!X14) -> 9.5087873 | S10: =IF(B10=0," ",(R10*(1-Q10)*M10)) -> 31.879623 | T10: =IF(B10=0," ",(1000*0.3*$D$5*(E10/2)^0.5)) -> 134.11694 | U10: =IF(B10=0," ",IF(S10<T10,1,0)) -> 1 | V10: =IF(B10="","",IF(U10=1,"KESME GÜVENLİĞİ SAĞLANMIŞTIR.","JET KOLONLARININ ÇAPINI , ARALIĞINI YA DA BETON DAYANIMINI ARTIRIN.")) -> KESME GÜVENLİĞİ SAĞLANMIŞTIR. | W10: =C10 -> 3
